Workbook

Sheet Additional_LU_and_deforestation
A1: Country | B1: AEZ | C1: Name | D1: ID | E1: HILDA_Additional_LU_Ha (2010-2018) | F1: =[1]Deforestation!E1 -> HILDA_deforestation_Ha | G1: Coef. GTAP
A2: =[1]Deforestation!A2 -> Indonesia | B2: =[1]Deforestation!B2 -> AEZ12 | C2: =[1]Deforestation!C2 -> v_f | D2: =[1]Deforestation!D2 -> Indonesia#AEZ12#v_f | E2: =_xlfn.IFNA(_xlfn.IFNA(VLOOKUP(D2,[2]Sheet1!$D:$E,2,FALSE),VLOOKUP(D2,[3]Sheet1!$D:$E,2,FALSE)),0) -> 8661.0655 | F2: =[1]Deforestation!E2 -> 321.67474 | G2: =IFERROR(IF((F2/E2)>1,1,F2/E2),0) -> 0.03714032
A3: =[1]Deforestation!A3 -> Angola | B3: =[1]Deforestation!B3 -> AEZ11 | C3: =[1]Deforestation!C3 -> osd | D3: =[1]Deforestation!D3 -> Angola#AEZ11#osd | E3: =_xlfn.IFNA(_xlfn.IFNA(VLOOKUP(D3,[2]Sheet1!$D:$E,2,FALSE),VLOOKUP(D3,[3]Sheet1!$D:$E,2,FALSE)),0) -> 201.99998 | F3: =[1]Deforestation!E3 -> 1373.9692 | G3: =IFERROR(IF((F3/E3)>1,1,F3/E3),0) -> 1
A4: =[1]Deforestation!A4 -> Peru | B4: =[1]Deforestation!B4 -> AEZ7 | C4: =[1]Deforestation!C4 -> pfb | D4: =[1]Deforestation!D4 -> Peru#AEZ7#pfb | E4: =_xlfn.IFNA(_xlfn.IFNA(VLOOKUP(D4,[2]Sheet1!$D:$E,2,FALSE),VLOOKUP(D4,[3]Sheet1!$D:$E,2,FALSE)),0) -> 2387.1865 | F4: =[1]Deforestation!E4 -> 3.153044 | G4: =IFERROR(IF((F4/E4)>1,1,F4/E4),0) -> 0.0013208201
A5: =[1]Deforestation!A5 -> Bolivia | B5: =[1]Deforestation!B5 -> AEZ5 | C5: =[1]Deforestation!C5 -> ocr | D5: =[1]Deforestation!D5 -> Bolivia#AEZ5#ocr | E5: =_xlfn.IFNA(_xlfn.IFNA(VLOOKUP(D5,[2]Sheet1!$D:$E,2,FALSE),VLOOKUP(D5,[3]Sheet1!$D:$E,2,FALSE)),0) -> 5758.8076 | F5: =[1]Deforestation!E5 -> 820.32056 | G5: =IFERROR(IF((F5/E5)>1,1,F5/E5),0) -> 0.14244625
A6: =[1]Deforestation!A6 -> Argentina | B6: =[1]Deforestation!B6 -> AEZ5 | C6: =[1]Deforestation!C6 -> pfb | D6: =[1]Deforestation!D6 -> Argentina#AEZ5#pfb | E6: =_xlfn.IFNA(_xlfn.IFNA(VLOOKUP(D6,[2]Sheet1!$D:$E,2,FALSE),VLOOKUP(D6,[3]Sheet1!$D:$E,2,FALSE)),0) -> 3361.2054 | F6: =[1]Deforestation!E6 -> 37.360096 | G6: =IFERROR(IF((F6/E6)>1,1,F6/E6),0) -> 0.011115089
A7: =[1]Deforestation!A7 -> Paraguay | B7: =[1]Deforestation!B7 -> AEZ6 | C7: =[1]Deforestation!C7 -> osd | D7: =[1]Deforestation!D7 -> Paraguay#AEZ6#osd | E7: =_xlfn.IFNA(_xlfn.IFNA(VLOOKUP(D7,[2]Sheet1!$D:$E,2,FALSE),VLOOKUP(D7,[3]Sheet1!$D:$E,2,FALSE)),0) -> 401249.43 | F7: =[1]Deforestation!E7 -> 119171.13 | G7: =IFERROR(IF((F7/E7)>1,1,F7/E7),0) -> 0.29700013
A8: =[1]Deforestation!A8 -> Colombia | B8: =[1]Deforestation!B8 -> AEZ4 | C8: =[1]Deforestation!C8 -> gro | D8: =[1]Deforestation!D8 -> Colombia#AEZ4#gro | E8: =_xlfn.IFNA(_xlfn.IFNA(VLOOKUP(D8,[2]Sheet1!$D:$E,2,FALSE),VLOOKUP(D8,[3]Sheet1!$D:$E,2,FALSE)),0) -> 1895.9338 | F8: =[1]Deforestation!E8 -> 161.89856 | G8: =IFERROR(IF((F8/E8)>1,1,F8/E8),0) -> 0.085392515
A9: =[1]Deforestation!A9 -> Paraguay | B9: =[1]Deforestation!B9 -> AEZ2 | C9: =[1]Deforestation!C9 -> v_f | D9: =[1]Deforestation!D9 -> Paraguay#AEZ2#v_f | E9: =_xlfn.IFNA(_xlfn.IFNA(VLOOKUP(D9,[2]Sheet1!$D:$E,2,FALSE),VLOOKUP(D9,[3]Sheet1!$D:$E,2,FALSE)),0) -> 1.1524575 | F9: =[1]Deforestation!E9 -> 9900 | G9: =IFERROR(IF((F9/E9)>1,1,F9/E9),0) -> 1
A10: =[1]Deforestation!A10 -> Argentina | B10: =[1]Deforestation!B10 -> AEZ5 | C10: =[1]Deforestation!C10 -> gro | D10: =[1]Deforestation!D10 -> Argentina#AEZ5#gro | E10: =_xlfn.IFNA(_xlfn.IFNA(VLOOKUP(D10,[2]Sheet1!$D:$E,2,FALSE),VLOOKUP(D10,[3]Sheet1!$D:$E,2,FALSE)),0) -> 18921.44 | F10: =[1]Deforestation!E10 -> 161.82416 | G10: =IFERROR(IF((F10/E10)>1,1,F10/E10),0) -> 0.0085524232
A11: =[1]Deforestation!A11 -> Paraguay | B11: =[1]Deforestation!B11 -> AEZ10 | C11: =[1]Deforestation!C11 -> v_f | D11: =[1]Deforestation!D11 -> Paraguay#AEZ10#v_f | E11: =_xlfn.IFNA(_xlfn.IFNA(VLOOKUP(D11,[2]Sheet1!$D:$E,2,FALSE),VLOOKUP(D11,[3]Sheet1!$D:$E,2,FALSE)),0) -> 0 | F11: =[1]Deforestation!E11 -> 0 | G11: =IFERROR(IF((F11/E11)>1,1,F11/E11),0) -> 0
A12: =[1]Deforestation!A12 -> Angola | B12: =[1]Deforestation!B12 -> AEZ5 | C12: =[1]Deforestation!C12 -> pfb | D12: =[1]Deforestation!D12 -> Angola#AEZ5#pfb | E12: =_xlfn.IFNA(_xlfn.IFNA(VLOOKUP(D12,[2]Sheet1!$D:$E,2,FALSE),VLOOKUP(D12,[3]Sheet1!$D:$E,2,FALSE)),0) -> 315.54043 | F12: =[1]Deforestation!E12 -> 17.751423 | G12: =IFERROR(IF((F12/E12)>1,1,F12/E12),0) -> 0.056257207
A13: =[1]Deforestation!A13 -> Peru | B13: =[1]Deforestation!B13 -> AEZ5 | C13: =[1]Deforestation!C13 -> pdr | D13: =[1]Deforestation!D13 -> Peru#AEZ5#pdr | E13: =_xlfn.IFNA(_xlfn.IFNA(VLOOKUP(D13,[2]Sheet1!$D:$E,2,FALSE),VLOOKUP(D13,[3]Sheet1!$D:$E,2,FALSE)),0) -> 985.32001 | F13: =[1]Deforestation!E13 -> 70.947205 | G13: =IFERROR(IF((F13/E13)>1,1,F13/E13),0) -> 0.072004226
... A572: =[1]Deforestation!A572 -> Peru | B572: =[1]Deforestation!B572 -> AEZ12 | C572: =[1]Deforestation!C572 -> ctl | D572: =[1]Deforestation!D572 -> Peru#AEZ12#ctl | E572: =_xlfn.IFNA(_xlfn.IFNA(VLOOKUP(D572,[2]Sheet1!$D:$E,2,FALSE),VLOOKUP(D572,[3]Sheet1!$D:$E,2,FALSE)),0) -> 116700 | F572: =[1]Deforestation!E572 -> 84400 | G572: =IFERROR(IF((F572/E572)>1,1,F572/E572),0) -> 0.72322194
A573: =[1]Deforestation!A573 -> Argentina | B573: =[1]Deforestation!B573 -> AEZ15 | C573: =[1]Deforestation!C573 -> ctl | D573: =[1]Deforestation!D573 -> Argentina#AEZ15#ctl | E573: =_xlfn.IFNA(_xlfn.IFNA(VLOOKUP(D573,[2]Sheet1!$D:$E,2,FALSE),VLOOKUP(D573,[3]Sheet1!$D:$E,2,FALSE)),0) -> 1500 | F573: =[1]Deforestation!E573 -> 34600 | G573: =IFERROR(IF((F573/E573)>1,1,F573/E573),0) -> 1 | O573: =2880900/8 -> 360112.5
A574: =[1]Deforestation!A574 -> Bolivia | B574: =[1]Deforestation!B574 -> AEZ9 | C574: =[1]Deforestation!C574 -> ctl | D574: =[1]Deforestation!D574 -> Bolivia#AEZ9#ctl | E574: =_xlfn.IFNA(_xlfn.IFNA(VLOOKUP(D574,[2]Sheet1!$D:$E,2,FALSE),VLOOKUP(D574,[3]Sheet1!$D:$E,2,FALSE)),0) -> 0 | F574: =[1]Deforestation!E574 -> 3700 | G574: =IFERROR(IF((F574/E574)>1,1,F574/E574),0) -> 0
A575: =[1]Deforestation!A575 -> Paraguay | B575: =[1]Deforestation!B575 -> AEZ5 | C575: =[1]Deforestation!C575 -> ctl | D575: =[1]Deforestation!D575 -> Paraguay#AEZ5#ctl | E575: =_xlfn.IFNA(_xlfn.IFNA(VLOOKUP(D575,[2]Sheet1!$D:$E,2,FALSE),VLOOKUP(D575,[3]Sheet1!$D:$E,2,FALSE)),0) -> 11500 | F575: =[1]Deforestation!E575 -> 18100 | G575: =IFERROR(IF((F575/E575)>1,1,F575/E575),0) -> 1
A576: =[1]Deforestation!A576 -> Argentina | B576: =[1]Deforestation!B576 -> AEZ12 | C576: =[1]Deforestation!C576 -> ctl | D576: =[1]Deforestation!D576 -> Argentina#AEZ12#ctl | E576: =_xlfn.IFNA(_xlfn.IFNA(VLOOKUP(D576,[2]Sheet1!$D:$E,2,FALSE),VLOOKUP(D576,[3]Sheet1!$D:$E,2,FALSE)),0) -> 0 | F576: =[1]Deforestation!E576 -> 36300 | G576: =IFERROR(IF((F576/E576)>1,1,F576/E576),0) -> 0
A577: =[1]Deforestation!A577 -> Ghana | B577: =[1]Deforestation!B577 -> AEZ6 | C577: =[1]Deforestation!C577 -> ctl | D577: =[1]Deforestation!D577 -> Ghana#AEZ6#ctl | E577: =_xlfn.IFNA(_xlfn.IFNA(VLOOKUP(D577,[2]Sheet1!$D:$E,2,FALSE),VLOOKUP(D577,[3]Sheet1!$D:$E,2,FALSE)),0) -> 5300 | F577: =[1]Deforestation!E577 -> 7700 | G577: =IFERROR(IF((F577/E577)>1,1,F577/E577),0) -> 1
A578: =[1]Deforestation!A578 -> Brazil | B578: =[1]Deforestation!B578 -> AEZ6 | C578: =[1]Deforestation!C578 -> ctl | D578: =[1]Deforestation!D578 -> Brazil#AEZ6#ctl | E578: =_xlfn.IFNA(_xlfn.IFNA(VLOOKUP(D578,[2]Sheet1!$D:$E,2,FALSE),VLOOKUP(D578,[3]Sheet1!$D:$E,2,FALSE)),0) -> 1679200 | F578: =[1]Deforestation!E578 -> 1433500 | G578: =IFERROR(IF((F578/E578)>1,1,F578/E578),0) -> 0.85368032
A579: =[1]Deforestation!A579 -> Bolivia | B579: =[1]Deforestation!B579 -> AEZ11 | C579: =[1]Deforestation!C579 -> ctl | D579: =[1]Deforestation!D579 -> Bolivia#AEZ11#ctl | E579: =_xlfn.IFNA(_xlfn.IFNA(VLOOKUP(D579,[2]Sheet1!$D:$E,2,FALSE),VLOOKUP(D579,[3]Sheet1!$D:$E,2,FALSE)),0) -> 9900 | F579: =[1]Deforestation!E579 -> 20200 | G579: =IFERROR(IF((F579/E579)>1,1,F579/E579),0) -> 1
A580: =[1]Deforestation!A580 -> Argentina | B580: =[1]Deforestation!B580 -> AEZ9 | C580: =[1]Deforestation!C580 -> ctl | D580: =[1]Deforestation!D580 -> Argentina#AEZ9#ctl | E580: =_xlfn.IFNA(_xlfn.IFNA(VLOOKUP(D580,[2]Sheet1!$D:$E,2,FALSE),VLOOKUP(D580,[3]Sheet1!$D:$E,2,FALSE)),0) -> 0 | F580: =[1]Deforestation!E580 -> 24500 | G580: =IFERROR(IF((F580/E580)>1,1,F580/E580),0) -> 0
A581: =[1]Deforestation!A581 -> Peru | B581: =[1]Deforestation!B581 -> AEZ9 | C581: =[1]Deforestation!C581 -> ctl | D581: =[1]Deforestation!D581 -> Peru#AEZ9#ctl | E581: =_xlfn.IFNA(_xlfn.IFNA(VLOOKUP(D581,[2]Sheet1!$D:$E,2,FALSE),VLOOKUP(D581,[3]Sheet1!$D:$E,2,FALSE)),0) -> 14900 | F581: =[1]Deforestation!E581 -> 6300 | G581: =IFERROR(IF((F581/E581)>1,1,F581/E581),0) -> 0.42281879
A582: =[1]Deforestation!A582 -> Indonesia | B582: =[1]Deforestation!B582 -> AEZ6 | C582: =[1]Deforestation!C582 -> ctl | D582: =[1]Deforestation!D582 -> Indonesia#AEZ6#ctl | E582: =_xlfn.IFNA(_xlfn.IFNA(VLOOKUP(D582,[2]Sheet1!$D:$E,2,FALSE),VLOOKUP(D582,[3]Sheet1!$D:$E,2,FALSE)),0) -> 137000 | F582: =[1]Deforestation!E582 -> 546400 | G582: =IFERROR(IF((F582/E582)>1,1,F582/E582),0) -> 1
A583: =[1]Deforestation!A583 -> Colombia | B583: =[1]Deforestation!B583 -> AEZ6 | C583: =[1]Deforestation!C583 -> ctl | D583: =[1]Deforestation!D583 -> Colombia#AEZ6#ctl | E583: =_xlfn.IFNA(_xlfn.IFNA(VLOOKUP(D583,[2]Sheet1!$D:$E,2,FALSE),VLOOKUP(D583,[3]Sheet1!$D:$E,2,FALSE)),0) -> 1657900 | F583: =[1]Deforestation!E583 -> 444000 | G583: =IFERROR(IF((F583/E583)>1,1,F583/E583),0) -> 0.26780867
A584: =[1]Deforestation!A584 -> Ghana | B584: =[1]Deforestation!B584 -> AEZ4 | C584: =[1]Deforestation!C584 -> ctl | D584: =[1]Deforestation!D584 -> Ghana#AEZ4#ctl | E584: =_xlfn.IFNA(_xlfn.IFNA(VLOOKUP(D584,[2]Sheet1!$D:$E,2,FALSE),VLOOKUP(D584,[3]Sheet1!$D:$E,2,FALSE)),0) -> 29700 | F584: =[1]Deforestation!E584 -> 11100 | G584: =IFERROR(IF((F584/E584)>1,1,F584/E584),0) -> 0.37373737
A585: =[1]Deforestation!A585 -> DRC | B585: =[1]Deforestation!B585 -> AEZ11 | C585: =[1]Deforestation!C585 -> ctl | D585: =[1]Deforestation!D585 -> DRC#AEZ11#ctl | E585: =_xlfn.IFNA(_xlfn.IFNA(VLOOKUP(D585,[2]Sheet1!$D:$E,2,FALSE),VLOOKUP(D585,[3]Sheet1!$D:$E,2,FALSE)),0) -> 600 | F585: =[1]Deforestation!E585 -> 2000 | G585: =IFERROR(IF((F585/E585)>1,1,F585/E585),0) -> 1
... A587: =[1]Deforestation!A587 -> Argentina | B587: =[1]Deforestation!B587 -> AEZ14 | C587: =[1]Deforestation!C587 -> ctl | D587: =[1]Deforestation!D587 -> Argentina#AEZ14#ctl | E587: =_xlfn.IFNA(_xlfn.IFNA(VLOOKUP(D587,[2]Sheet1!$D:$E,2,FALSE),VLOOKUP(D587,[3]Sheet1!$D:$E,2,FALSE)),0) -> 0 | F587: =[1]Deforestation!E587 -> 2000 | G587: =IFERROR(IF((F587/E587)>1,1,F587/E587),0) -> 0

Sheet Land_Cover
A1: =[4]Land_Cover!A1 -> year | B1: =[4]Land_Cover!B1 -> country | C1: =[4]Land_Cover!C1 -> AEZ | D1: =[4]Land_Cover!D1 -> Name | E1: =[4]Land_Cover!E1 -> ID | F1: =[4]Land_Cover!F1 -> FAO_Annual_Coverage
A2: =[4]Land_Cover!A2 -> 2015 | B2: =[4]Land_Cover!B2 -> Colombia | C2: =[4]Land_Cover!C2 -> AEZ12 | D2: =[4]Land_Cover!D2 -> wht | E2: =[4]Land_Cover!E2 -> Colombia#AEZ12#wht | F2: =[4]Land_Cover!F2 -> 2842.7372
A3: =[4]Land_Cover!A3 -> 2012 | B3: =[4]Land_Cover!B3 -> DRC | C3: =[4]Land_Cover!C3 -> AEZ8 | D3: =[4]Land_Cover!D3 -> pdr | E3: =[4]Land_Cover!E3 -> DRC#AEZ8#pdr | F3: =[4]Land_Cover!F3 -> 90.10576
A4: =[4]Land_Cover!A4 -> 2017 | B4: =[4]Land_Cover!B4 -> Paraguay | C4: =[4]Land_Cover!C4 -> AEZ4 | D4: =[4]Land_Cover!D4 -> v_f | E4: =[4]Land_Cover!E4 -> Paraguay#AEZ4#v_f | F4: =[4]Land_Cover!F4 -> 1076.0358
A5: =[4]Land_Cover!A5 -> 2010 | B5: =[4]Land_Cover!B5 -> Ghana | C5: =[4]Land_Cover!C5 -> AEZ2 | D5: =[4]Land_Cover!D5 -> pdr | E5: =[4]Land_Cover!E5 -> Ghana#AEZ2#pdr | F5: =[4]Land_Cover!F5 -> 1702.9687
A6: =[4]Land_Cover!A6 -> 2015 | B6: =[4]Land_Cover!B6 -> Ivory Coast | C6: =[4]Land_Cover!C6 -> AEZ6 | D6: =[4]Land_Cover!D6 -> ocr | E6: =[4]Land_Cover!E6 -> Ivory Coast#AEZ6#ocr | F6: =[4]Land_Cover!F6 -> 1363972.4
A7: =[4]Land_Cover!A7 -> 2017 | B7: =[4]Land_Cover!B7 -> Bolivia | C7: =[4]Land_Cover!C7 -> AEZ4 | D7: =[4]Land_Cover!D7 -> c_b | E7: =[4]Land_Cover!E7 -> Bolivia#AEZ4#c_b | F7: =[4]Land_Cover!F7 -> 10442.817
A8: =[4]Land_Cover!A8 -> 2015 | B8: =[4]Land_Cover!B8 -> Argentina | C8: =[4]Land_Cover!C8 -> AEZ12 | D8: =[4]Land_Cover!D8 -> gro | E8: =[4]Land_Cover!E8 -> Argentina#AEZ12#gro | F8: =[4]Land_Cover!F8 -> 4541644.9
A9: =[4]Land_Cover!A9 -> 2014 | B9: =[4]Land_Cover!B9 -> Colombia | C9: =[4]Land_Cover!C9 -> AEZ4 | D9: =[4]Land_Cover!D9 -> wht | E9: =[4]Land_Cover!E9 -> Colombia#AEZ4#wht | F9: =[4]Land_Cover!F9 -> 48.043796
A10: =[4]Land_Cover!A10 -> 2017 | B10: =[4]Land_Cover!B10 -> Indonesia | C10: =[4]Land_Cover!C10 -> AEZ5 | D10: =[4]Land_Cover!D10 -> pfb | E10: =[4]Land_Cover!E10 -> Indonesia#AEZ5#pfb | F10: =[4]Land_Cover!F10 -> 563.98746
A11: =[4]Land_Cover!A11 -> 2012 | B11: =[4]Land_Cover!B11 -> Bolivia | C11: =[4]Land_Cover!C11 -> AEZ4 | D11: =[4]Land_Cover!D11 -> pfb | E11: =[4]Land_Cover!E11 -> Bolivia#AEZ4#pfb | F11: =[4]Land_Cover!F11 -> 262.00873
A12: =[4]Land_Cover!A12 -> 2012 | B12: =[4]Land_Cover!B12 -> Brazil | C12: =[4]Land_Cover!C12 -> AEZ1 | D12: =[4]Land_Cover!D12 -> pdr | E12: =[4]Land_Cover!E12 -> Brazil#AEZ1#pdr | F12: =[4]Land_Cover!F12 -> 310.4706
... A6229: =[4]Land_Cover!A6229 -> 2018 | B6229: =[4]Land_Cover!B6229 -> DRC | C6229: =[4]Land_Cover!C6229 -> AEZ6 | D6229: =[4]Land_Cover!D6229 -> pdr | E6229: =[4]Land_Cover!E6229 -> DRC#AEZ6#pdr | F6229: =[4]Land_Cover!F6229 -> 292493.87
A6230: =[5]Land_Cover!A2 -> 2015 | B6230: =[5]Land_Cover!B2 -> Brazil | C6230: =[5]Land_Cover!C2 -> AEZ1 | D6230: =[5]Land_Cover!D2 -> ctl | E6230: =[5]Land_Cover!E2 -> Brazil#AEZ1#ctl | F6230: =[5]Land_Cover!F2 -> 231100
A6231: =[5]Land_Cover!A3 -> 2016 | B6231: =[5]Land_Cover!B3 -> Bolivia | C6231: =[5]Land_Cover!C3 -> AEZ11 | D6231: =[5]Land_Cover!D3 -> ctl | E6231: =[5]Land_Cover!E3 -> Bolivia#AEZ11#ctl | F6231: =[5]Land_Cover!F3 -> 874600
A6232: =[5]Land_Cover!A4 -> 2010 | B6232: =[5]Land_Cover!B4 -> Brazil | C6232: =[5]Land_Cover!C4 -> AEZ6 | D6232: =[5]Land_Cover!D4 -> ctl | E6232: =[5]Land_Cover!E4 -> Brazil#AEZ6#ctl | F6232: =[5]Land_Cover!F4 -> 27417300
A6233: =[5]Land_Cover!A5 -> 2010 | B6233: =[5]Land_Cover!B5 -> Angola | C6233: =[5]Land_Cover!C5 -> AEZ9 | D6233: =[5]Land_Cover!D5 -> ctl | E6233: =[5]Land_Cover!E5 -> Angola#AEZ9#ctl | F6233: =[5]Land_Cover!F5 -> 1623100
A6234: =[5]Land_Cover!A6 -> 2017 | B6234: =[5]Land_Cover!B6 -> Brazil | C6234: =[5]Land_Cover!C6 -> AEZ11 | D6234: =[5]Land_Cover!D6 -> ctl | E6234: =[5]Land_Cover!E6 -> Brazil#AEZ11#ctl | F6234: =[5]Land_Cover!F6 -> 660000
A6235: =[5]Land_Cover!A7 -> 2010 | B6235: =[5]Land_Cover!B7 -> Peru | C6235: =[5]Land_Cover!C7 -> AEZ11 | D6235: =[5]Land_Cover!D7 -> ctl | E6235: =[5]Land_Cover!E7 -> Peru#AEZ11#ctl | F6235: =[5]Land_Cover!F7 -> 4051900
A6236: =[5]Land_Cover!A8 -> 2011 | B6236: =[5]Land_Cover!B8 -> Colombia | C6236: =[5]Land_Cover!C8 -> AEZ8 | D6236: =[5]Land_Cover!D8 -> ctl | E6236: =[5]Land_Cover!E8 -> Colombia#AEZ8#ctl | F6236: =[5]Land_Cover!F8 -> 500
A6237: =[5]Land_Cover!A9 -> 2013 | B6237: =[5]Land_Cover!B9 -> Bolivia | C6237: =[5]Land_Cover!C9 -> AEZ5 | D6237: =[5]Land_Cover!D9 -> ctl | E6237: =[5]Land_Cover!E9 -> Bolivia#AEZ5#ctl | F6237: =[5]Land_Cover!F9 -> 3086400
A6238: =[5]Land_Cover!A10 -> 2018 | B6238: =[5]Land_Cover!B10 -> Paraguay | C6238: =[5]Land_Cover!C10 -> AEZ12 | D6238: =[5]Land_Cover!D10 -> ctl | E6238: =[5]Land_Cover!E10 -> Paraguay#AEZ12#ctl | F6238: =[5]Land_Cover!F10 -> 3796400
A6239: =[5]Land_Cover!A11 -> 2011 | B6239: =[5]Land_Cover!B11 -> Paraguay | C6239: =[5]Land_Cover!C11 -> AEZ6 | D6239: =[5]Land_Cover!D11 -> ctl | E6239: =[5]Land_Cover!E11 -> Paraguay#AEZ6#ctl | F6239: =[5]Land_Cover!F11 -> 3582500
A6240: =[5]Land_Cover!A12 -> 2017 | B6240: =[5]Land_Cover!B12 -> Angola | C6240: =[5]Land_Cover!C12 -> AEZ8 | D6240: =[5]Land_Cover!D12 -> ctl | E6240: =[5]Land_Cover!E12 -> Angola#AEZ8#ctl | F6240: =[5]Land_Cover!F12 -> 260100
A6241: =[5]Land_Cover!A13 -> 2017 | B6241: =[5]Land_Cover!B13 -> Bolivia | C6241: =[5]Land_Cover!C13 -> AEZ3 | D6241: =[5]Land_Cover!D13 -> ctl | E6241: =[5]Land_Cover!E13 -> Bolivia#AEZ3#ctl | F6241: =[5]Land_Cover!F13 -> 84300
... A7082: =[5]Land_Cover!A854 -> 2018 | B7082: =[5]Land_Cover!B854 -> Peru | C7082: =[5]Land_Cover!C854 -> AEZ10 | D7082: =[5]Land_Cover!D854 -> ctl | E7082: =[5]Land_Cover!E854 -> Peru#AEZ10#ctl | F7082: =[5]Land_Cover!F854 -> 4081000

Sheet Land_Cover_MIN_MAX
A1: ID | B1: HILDA_Land_Cover_MIN_Ha | C1: HILDA_Land_Cover_MAX_Ha
A2: Angola#AEZ1#c_b | B2: =_xlfn.MINIFS(Land_Cover!F:F,Land_Cover!E:E,A2) -> 46.420672 | C2: =_xlfn.MAXIFS(Land_Cover!F:F,Land_Cover!E:E,A2) -> 67.782946
A3: Angola#AEZ10#c_b | B3: =_xlfn.MINIFS(Land_Cover!F:F,Land_Cover!E:E,A3) -> 615.0739 | C3: =_xlfn.MAXIFS(Land_Cover!F:F,Land_Cover!E:E,A3) -> 898.12403
A4: Angola#AEZ11#c_b | B4: =_xlfn.MINIFS(Land_Cover!F:F,Land_Cover!E:E,A4) -> 17.407752 | C4: =_xlfn.MAXIFS(Land_Cover!F:F,Land_Cover!E:E,A4) -> 25.418605
A5: Angola#AEZ12#c_b | B5: =_xlfn.MINIFS(Land_Cover!F:F,Land_Cover!E:E,A5) -> 0 | C5: =_xlfn.MAXIFS(Land_Cover!F:F,Land_Cover!E:E,A5) -> 0
A6: Angola#AEZ13#c_b | B6: =_xlfn.MINIFS(Land_Cover!F:F,Land_Cover!E:E,A6) -> 0 | C6: =_xlfn.MAXIFS(Land_Cover!F:F,Land_Cover!E:E,A6) -> 0
A7: Angola#AEZ14#c_b | B7: =_xlfn.MINIFS(Land_Cover!F:F,Land_Cover!E:E,A7) -> 0 | C7: =_xlfn.MAXIFS(Land_Cover!F:F,Land_Cover!E:E,A7) -> 0
A8: Angola#AEZ15#c_b | B8: =_xlfn.MINIFS(Land_Cover!F:F,Land_Cover!E:E,A8) -> 0 | C8: =_xlfn.MAXIFS(Land_Cover!F:F,Land_Cover!E:E,A8) -> 0
A9: Angola#AEZ16#c_b | B9: =_xlfn.MINIFS(Land_Cover!F:F,Land_Cover!E:E,A9) -> 0 | C9: =_xlfn.MAXIFS(Land_Cover!F:F,Land_Cover!E:E,A9) -> 0
A10: Angola#AEZ17#c_b | B10: =_xlfn.MINIFS(Land_Cover!F:F,Land_Cover!E:E,A10) -> 0 | C10: =_xlfn.MAXIFS(Land_Cover!F:F,Land_Cover!E:E,A10) -> 0
A11: Angola#AEZ18#c_b | B11: =_xlfn.MINIFS(Land_Cover!F:F,Land_Cover!E:E,A11) -> 0 | C11: =_xlfn.MAXIFS(Land_Cover!F:F,Land_Cover!E:E,A11) -> 0
A12: Angola#AEZ2#c_b | B12: =_xlfn.MINIFS(Land_Cover!F:F,Land_Cover!E:E,A12) -> 197.28786 | C12: =_xlfn.MAXIFS(Land_Cover!F:F,Land_Cover!E:E,A12) -> 288.07752
A13: Angola#AEZ3#c_b | B13: =_xlfn.MINIFS(Land_Cover!F:F,Land_Cover!E:E,A13) -> 1421.6331 | C13: =_xlfn.MAXIFS(Land_Cover!F:F,Land_Cover!E:E,A13) -> 2075.8527
... A1945: DRC#AEZ9#wht | B1945: =_xlfn.MINIFS(Land_Cover!F:F,Land_Cover!E:E,A1945) -> 8.0472813 | C1945: =_xlfn.MAXIFS(Land_Cover!F:F,Land_Cover!E:E,A1945) -> 11.015366

Sheet GTAP_area
A1: ID | B1: Country | C1: Crops | D1: AEZ | E1: GTAP 2014 Harvested Area (KHa) | F1: Value Ha
A2: =_xlfn.CONCAT(B2,"#",D2,"#",C2) -> Angola#AEZ1#c_b | B2: Angola | C2: c_b | D2: AEZ1 | E2: 0.08 | F2: =E2*1000 -> 80
A3: =_xlfn.CONCAT(B3,"#",D3,"#",C3) -> Angola#AEZ2#c_b | B3: Angola | C3: c_b | D3: AEZ2 | E3: 0.34 | F3: =E3*1000 -> 340
A4: =_xlfn.CONCAT(B4,"#",D4,"#",C4) -> Angola#AEZ3#c_b | B4: Angola | C4: c_b | D4: AEZ3 | E4: 2.45 | F4: =E4*1000 -> 2450
A5: =_xlfn.CONCAT(B5,"#",D5,"#",C5) -> Angola#AEZ4#c_b | B5: Angola | C5: c_b | D5: AEZ4 | E5: 10.3 | F5: =E5*1000 -> 10300
A6: =_xlfn.CONCAT(B6,"#",D6,"#",C6) -> Angola#AEZ5#c_b | B6: Angola | C6: c_b | D6: AEZ5 | E6: 5.09 | F6: =E6*1000 -> 5090
A7: =_xlfn.CONCAT(B7,"#",D7,"#",C7) -> Angola#AEZ6#c_b | B7: Angola | C7: c_b | D7: AEZ6 | E7: 0 | F7: =E7*1000 -> 0
A8: =_xlfn.CONCAT(B8,"#",D8,"#",C8) -> Angola#AEZ7#c_b | B8: Angola | C8: c_b | D8: AEZ7 | E8: 0 | F8: =E8*1000 -> 0
A9: =_xlfn.CONCAT(B9,"#",D9,"#",C9) -> Angola#AEZ8#c_b | B9: Angola | C9: c_b | D9: AEZ8 | E9: 0 | F9: =E9*1000 -> 0
A10: =_xlfn.CONCAT(B10,"#",D10,"#",C10) -> Angola#AEZ9#c_b | B10: Angola | C10: c_b | D10: AEZ9 | E10: 0 | F10: =E10*1000 -> 0
A11: =_xlfn.CONCAT(B11,"#",D11,"#",C11) -> Angola#AEZ10#c_b | B11: Angola | C11: c_b | D11: AEZ10 | E11: 1.06 | F11: =E11*1000 -> 1060
A12: =_xlfn.CONCAT(B12,"#",D12,"#",C12) -> Angola#AEZ11#c_b | B12: Angola | C12: c_b | D12: AEZ11 | E12: 0.03 | F12: =E12*1000 -> 30
A13: =_xlfn.CONCAT(B13,"#",D13,"#",C13) -> Angola#AEZ12#c_b | B13: Angola | C13: c_b | D13: AEZ12 | E13: 0 | F13: =E13*1000 -> 0
... A6805: =_xlfn.CONCAT(B6805,"#",D6805,"#",C6805) -> Mozambique#AEZ18#ctl | B6805: Mozambique | C6805: ctl | D6805: AEZ18 | E6805: 0 | F6805: =E6805*1000 -> 0

Sheet Sheet3
A3: Sum of Coef. GTAP | B3: Column Labels
A4: Row Labels | B4: c_b | C4: ctl | D4: gro | E4: ocr | F4: osd | G4: pdr | H4: pfb | I4: v_f | J4: wht | K4: (blank) | L4: Grand Total
A5: Argentina | B5: 0.98698483 | C5: 3 | D5: 1.3271709 | E5: 1.2604854 | F5: 1.3058881 | G5: 0.36575447 | H5: 1.2126515 | I5: 0.41549425 | J5: 0.71576854 | L5: 10.590198
A6: AEZ10 | B6: 0.12697056 | C6: 0 | D6: 0.12456732 | E6: 0.16629647 | F6: 0.12796852 | G6: 0.24124632 | H6: 0.16423189 | I6: 0.03637 | J6: 0.062655819 | L6: 1.0503069
A7: AEZ11 | B7: 0.028520055 | C7: 0 | D7: 0.026165594 | E7: 0.032499219 | F7: 0.024622509 | G7: 0.040948827 | H7: 0.030987746 | I7: 0.01192 | J7: 0.017235959 | L7: 0.21289991
A8: AEZ12 | B8: 0.0030426402 | C8: 0 | D8: 0.002192635 | E8: 0.0023504363 | F8: 0.002497589 | G8: 0.003311598 | H8: 0.0028167032 | I8: 0.0016391487 | J8: 0.0015688205 | L8: 0.019419571
A9: AEZ14 | C9: 0 | L9: 0
A10: AEZ15 | B10: 0 | C10: 1 | D10: 0.12562473 | E10: 0 | F10: 0.13616829 | G10: 0 | H10: 0 | I10: 0.026944703 | J10: 0.066360358 | L10: 1.3550981
A11: AEZ16 | B11: 0 | C11: 1 | D11: 0.22388285 | E11: 0 | F11: 0.21517194 | G11: 0 | H11: 0 | I11: 0.074306466 | J11: 0.10486206 | L11: 1.6182233
A12: AEZ4 | B12: 0.59582047 | C12: 0 | D12: 0.56875111 | E12: 0.71377662 | F12: 0.55082453 | G12: 0 | H12: 0.70103175 | I12: 0.17546635 | J12: 0.30576719 | L12: 3.611438
A13: AEZ5 | B13: 0.0095566583 | C13: 1 | D13: 0.0085524232 | E13: 0.010904969 | F13: 0.0085979921 | G13: 0.016101235 | H13: 0.011115089 | I13: 0.002476916 | J13: 0.0041901518 | L13: 1.0714954
A14: AEZ7 | B14: 0.047155261 | D14: 0.053103055 | E14: 0.068917627 | F14: 0.037500693 | G14: 0.051917336 | H14: 0.045906234 | I14: 0.032489797 | J14: 0.053296677 | L14: 0.39028668
A15: AEZ8 | B15: 0 | C15: 0 | D15: 0.0061723516 | E15: 0.0084428521 | F15: 0.0063403637 | G15: 0.012229164 | H15: 0.0081965302 | I15: 0.0016584522 | J15: 0.0030899175 | L15: 0.046129631
A16: AEZ9 | B16: 0.17591918 | C16: 0 | D16: 0.18815882 | E16: 0.25729722 | F16: 0.19619566 | G16: 0 | H16: 0.24836554 | I16: 0.052222414 | J16: 0.096741583 | L16: 1.2149004
A17: Bolivia | B17: 2.1337321 | C17: 7 | D17: 1.5892098 | E17: 1.676427 | F17: 1.887742 | G17: 1.6532269 | H17: 2.0208781 | I17: 2.4761722 | J17: 1.8063072 | L17: 22.243695
A18: AEZ10 | B18: 0.0080833443 | C18: 1 | D18: 0.0038949992 | E18: 0.0014543762 | F18: 0.0047079945 | G18: 0.0029020159 | H18: 0.0080792899 | I18: 0.0011725803 | J18: 0.0059926665 | L18: 1.0362873
A19: AEZ11 | C19: 1 | L19: 1
A20: AEZ12 | C20: 1 | L20: 1
A21: AEZ3 | B21: 0 | C21: 1 | D21: 0 | E21: 0 | F21: 0 | G21: 0 | H21: 0 | I21: 1 | J21: 0 | L21: 2
A22: AEZ4 | B22: 1 | C22: 1 | D22: 0.90674071 | E22: 0.86097321 | F22: 1 | G22: 1 | H22: 1 | I22: 0.82246753 | J22: 1 | L22: 8.5901815
A23: AEZ5 | B23: 0.27188611 | C23: 1 | D23: 0.15584769 | E23: 0.14244625 | F23: 0.1981953 | G23: 0.18082445 | H23: 0.2626485 | I23: 0.13291272 | J23: 0.22855515 | L23: 2.5733162
A24: AEZ6 | B24: 0.85376269 | C24: 1 | D24: 0.5227264 | E24: 0.67155319 | F24: 0.68483868 | G24: 0.46950041 | H24: 0.75015035 | I24: 0.51961935 | J24: 0.57175934 | L24: 6.0439104
A25: AEZ9 | C25: 0 | L25: 0
A26: Brazil | B26: 0.27207879 | C26: 4.0372161 | D26: 0.29909935 | E26: 0.23990305 | F26: 0.34991484 | G26: 0.29717519 | H26: 0.2249092 | I26: 0.30187454 | J26: 0.39182719 | L26: 6.4139982
A27: AEZ11 | B27: 0.017036242 | C27: 0.15789474 | D27: 0.010825383 | E27: 0.0066717282 | F27: 0.016116594 | G27: 0.0035732709 | H27: 0.008252087 | I27: 0.017699467 | J27: 0.025351405 | L27: 0.26342091
A28: AEZ12 | B28: 0.066629267 | C28: 1 | D28: 0.062325577 | E28: 0.051102061 | F28: 0.088409329 | G28: 0.052084297 | H28: 0.045561629 | I28: 0.079222777 | J28: 0.1078766 | L28: 1.5532115
A29: AEZ3 | B29: 0.015211084 | C29: 0.025641026 | D29: 0.0035223403 | E29: 0.019090677 | F29: 0.0058209552 | G29: 0.011427724 | H29: 0.011187716 | I29: 0.014681807 | J29: 0.002935345 | L29: 0.10951867
A30: AEZ4 | B30: 0.021570067 | C30: 1 | D30: 0.016890063 | E30: 0.023408285 | F30: 0.016967872 | G30: 0.018646067 | H30: 0.018927147 | I30: 0.020360606 | J30: 0.015896077 | L30: 1.1526662
A31: AEZ5 | B31: 0.12032318 | C31: 1 | D31: 0.17533508 | E31: 0.10540351 | F31: 0.19225335 | G31: 0.17521661 | H31: 0.11050943 | I31: 0.13779944 | J31: 0.20749235 | L31: 2.224333
A32: AEZ6 | B32: 0.031308957 | C32: 0.85368032 | D32: 0.030200903 | E32: 0.034226791 | F32: 0.030346739 | G32: 0.036227216 | H32: 0.030471186 | I32: 0.032110444 | J32: 0.032275411 | L32: 1.110848
A33: Paraguay | B33: 1.7156515 | C33: 2.9574468 | D33: 1.9084619 | E33: 2.0206103 | F33: 1.8609433 | G33: 1.8349962 | H33: 0.72167202 | I33: 3.8731749 | J33: 1.6205249 | L33: 18.513482
A34: AEZ10 | B34: 0 | D34: 0 | E34: 0 | F34: 0 | G34: 0 | H34: 0 | I34: 0 | J34: 0 | L34: 0
A35: AEZ12 | B35: 0.23490287 | C35: 0 | D35: 0.31688231 | E35: 0.31767066 | F35: 0.32351088 | G35: 0.28705026 | H35: 0.2538826 | I35: 0.29574281 | J35: 0.17709191 | L35: 2.2067343
A36: AEZ2 | B36: 0 | D36: 0 | E36: 0 | F36: 0 | G36: 0 | H36: 0 | I36: 1 | J36: 0 | L36: 1
A37: AEZ3 | B37: 0 | D37: 0 | E37: 0 | F37: 0 | G37: 0 | H37: 0 | I37: 1 | J37: 0 | L37: 1
A38: AEZ4 | B38: 1 | C38: 1 | D38: 1 | E38: 1 | F38: 1 | G38: 1 | H38: 0 | I38: 1 | J38: 1 | L38: 8
A39: AEZ5 | B39: 0.20582673 | C39: 1 | D39: 0.31151924 | E39: 0.40509664 | F39: 0.24043228 | G39: 0.27346993 | H39: 0.20321707 | I39: 0.27376353 | J39: 0.23176086 | L39: 3.1450863
A40: AEZ6 | B40: 0.27492194 | C40: 0.95744681 | D40: 0.28006036 | E40: 0.29784302 | F40: 0.29700013 | G40: 0.27447603 | H40: 0.26457235 | I40: 0.30366853 | J40: 0.21167211 | L40: 3.1616613
A41: (blank)
A42: (blank)
...

Sheet Sheet4
A1: ID | M1: HILDA Growth 2010-2018 [(Positiv add. LU 2010-2018)/min LC 2010-2018] | W1: GTAP_Area_Ha | AG1: GTAP_Additional_LU_Ha (based on HILDA shares) | AQ1: Coef. GTAP | BA1: GTAP_deforestation_Ha (based on HILDA shares) | BM1: Def._coefficient_for shocks | CG1: GTAP_Area_Ha (AEZ def.only)
C2: c_b | D2: ctl | E2: gro | F2: ocr | G2: osd | H2: pdr | I2: pfb | J2: v_f | K2: wht | M2: c_b | N2: ctl | O2: gro | P2: ocr | Q2: osd | R2: pdr | S2: pfb | T2: v_f | U2: wht | W2: c_b | X2: ctl | Y2: gro | Z2: ocr | AA2: osd | AB2: pdr | AC2: pfb | AD2: v_f | AE2: wht | AG2: c_b | AH2: ctl | AI2: gro | AJ2: ocr | AK2: osd | AL2: pdr | AM2: pfb | AN2: v_f | AO2: wht | AQ2: c_b | AR2: ctl | AS2: gro | AT2: ocr | AU2: osd | AV2: pdr | AW2: pfb | AX2: v_f | AY2: wht | BA2: c_b | BB2: ctl | BC2: gro | BD2: ocr | BE2: osd | BF2: pdr | BG2: pfb | BH2: v_f | BI2: wht | BM2: c_b | BN2: ctl | BO2: gro | BP2: ocr | BQ2: osd | BR2: pdr | BS2: pfb | BT2: v_f | BU2: wht | BW2: c_b | BX2: ctl | BY2: gro | BZ2: ocr | CA2: osd | CB2: pdr | CC2: pfb | CD2: v_f | CE2: wht | CG2: c_b | CH2: ctl | CI2: gro | CJ2: ocr | CK2: osd | CL2: pdr | CM2: pfb | CN2: v_f | CO2: wht
A3: Angola | B3: AEZ1 | C3: =_xlfn.CONCAT($A3,"#",$B3,"#",C$2) -> Angola#AEZ1#c_b | D3: =_xlfn.CONCAT($A3,"#",$B3,"#",D$2) -> Angola#AEZ1#ctl | E3: =_xlfn.CONCAT($A3,"#",$B3,"#",E$2) -> Angola#AEZ1#gro | F3: =_xlfn.CONCAT($A3,"#",$B3,"#",F$2) -> Angola#AEZ1#ocr | G3: =_xlfn.CONCAT($A3,"#",$B3,"#",G$2) -> Angola#AEZ1#osd | H3: =_xlfn.CONCAT($A3,"#",$B3,"#",H$2) -> Angola#AEZ1#pdr | I3: =_xlfn.CONCAT($A3,"#",$B3,"#",I$2) -> Angola#AEZ1#pfb | J3: =_xlfn.CONCAT($A3,"#",$B3,"#",J$2) -> Angola#AEZ1#v_f | K3: =_xlfn.CONCAT($A3,"#",$B3,"#",K$2) -> Angola#AEZ1#wht | M3: =IFERROR(_xlfn.IFNA(VLOOKUP(C3,Additional_LU_and_deforestation!$D:$E,2,FALSE)/VLOOKUP(C3,Land_Cover_MIN_MAX!$A:$C,2,FALSE),0),0) -> 0 | N3: =IFERROR(_xlfn.IFNA(VLOOKUP(D3,Additional_LU_and_deforestation!$D:$E,2,FALSE)/VLOOKUP(D3,Land_Cover_MIN_MAX!$A:$C,2,FALSE),0),0) -> 0 | O3: =IFERROR(_xlfn.IFNA(VLOOKUP(E3,Additional_LU_and_deforestation!$D:$E,2,FALSE)/VLOOKUP(E3,Land_Cover_MIN_MAX!$A:$C,2,FALSE),0),0) -> 0 | P3: =IFERROR(_xlfn.IFNA(VLOOKUP(F3,Additional_LU_and_deforestation!$D:$E,2,FALSE)/VLOOKUP(F3,Land_Cover_MIN_MAX!$A:$C,2,FALSE),0),0) -> 0 | Q3: =IFERROR(_xlfn.IFNA(VLOOKUP(G3,Additional_LU_and_deforestation!$D:$E,2,FALSE)/VLOOKUP(G3,Land_Cover_MIN_MAX!$A:$C,2,FALSE),0),0) -> 0 | R3: =IFERROR(_xlfn.IFNA(VLOOKUP(H3,Additional_LU_and_deforestation!$D:$E,2,FALSE)/VLOOKUP(H3,Land_Cover_MIN_MAX!$A:$C,2,FALSE),0),0) -> 0 | S3: =IFERROR(_xlfn.IFNA(VLOOKUP(I3,Additional_LU_and_deforestation!$D:$E,2,FALSE)/VLOOKUP(I3,Land_Cover_MIN_MAX!$A:$C,2,FALSE),0),0) -> 0 | T3: =IFERROR(_xlfn.IFNA(VLOOKUP(J3,Additional_LU_and_deforestation!$D:$E,2,FALSE)/VLOOKUP(J3,Land_Cover_MIN_MAX!$A:$C,2,FALSE),0),0) -> 0 | U3: =IFERROR(_xlfn.IFNA(VLOOKUP(K3,Additional_LU_and_deforestation!$D:$E,2,FALSE)/VLOOKUP(K3,Land_Cover_MIN_MAX!$A:$C,2,FALSE),0),0) -> 0 | W3: =VLOOKUP(C3,GTAP_area!$A:$F,6,FALSE) -> 80 | X3: =VLOOKUP(D3,GTAP_area!$A:$F,6,FALSE) -> 59940 | Y3: =VLOOKUP(E3,GTAP_area!$A:$F,6,FALSE) -> 7650 | Z3: =VLOOKUP(F3,GTAP_area!$A:$F,6,FALSE) -> 180 | AA3: =VLOOKUP(G3,GTAP_area!$A:$F,6,FALSE) -> 1530 | AB3: =VLOOKUP(H3,GTAP_area!$A:$F,6,FALSE) -> 20 | AC3: =VLOOKUP(I3,GTAP_area!$A:$F,6,FALSE) -> 20 | AD3: =VLOOKUP(J3,GTAP_area!$A:$F,6,FALSE) -> 8850 | AE3: =VLOOKUP(K3,GTAP_area!$A:$F,6,FALSE) -> 30 | AG3: =M3*W3 -> 0 | AH3: =N3*X3 -> 0 | AI3: =O3*Y3 -> 0 | AJ3: =P3*Z3 -> 0 | AK3: =Q3*AA3 -> 0 | AL3: =R3*AB3 -> 0 | AM3: =S3*AC3 -> 0 | AN3: =T3*AD3 -> 0 | AO3: =U3*AE3 -> 0 | AQ3: =IFERROR(GETPIVOTDATA("Coef. GTAP",Sheet3!$A$3,"Country",$A3,"AEZ",$B3,"Name",AQ$2),0) -> 0 | AR3: =IFERROR(GETPIVOTDATA("Coef. GTAP",Sheet3!$A$3,"Country",$A3,"AEZ",$B3,"Name",AR$2),0) -> 0 | AS3: =IFERROR(GETPIVOTDATA("Coef. GTAP",Sheet3!$A$3,"Country",$A3,"AEZ",$B3,"Name",AS$2),0) -> 0 | AT3: =IFERROR(GETPIVOTDATA("Coef. GTAP",Sheet3!$A$3,"Country",$A3,"AEZ",$B3,"Name",AT$2),0) -> 0 | AU3: =IFERROR(GETPIVOTDATA("Coef. GTAP",Sheet3!$A$3,"Country",$A3,"AEZ",$B3,"Name",AU$2),0) -> 0 | AV3: =IFERROR(GETPIVOTDATA("Coef. GTAP",Sheet3!$A$3,"Country",$A3,"AEZ",$B3,"Name",AV$2),0) -> 0 | AW3: =IFERROR(GETPIVOTDATA("Coef. GTAP",Sheet3!$A$3,"Country",$A3,"AEZ",$B3,"Name",AW$2),0) -> 0 | AX3: =IFERROR(GETPIVOTDATA("Coef. GTAP",Sheet3!$A$3,"Country",$A3,"AEZ",$B3,"Name",AX$2),0) -> 0 | AY3: =IFERROR(GETPIVOTDATA("Coef. GTAP",Sheet3!$A$3,"Country",$A3,"AEZ",$B3,"Name",AY$2),0) -> 0 | BA3: =AG3*AQ3 -> 0 | BB3: =AH3*AR3 -> 0 | BC3: =AI3*AS3 -> 0 | BD3: =AJ3*AT3 -> 0 | BE3: =AK3*AU3 -> 0 | BF3: =AL3*AV3 -> 0 | BG3: =AM3*AW3 -> 0 | BH3: =AN3*AX3 -> 0 | BI3: =AO3*AY3 -> 0 | BK3: =A3 -> Angola | BL3: AEZ1 | BM3: =IFERROR(BA3/W3*100,0) -> 0 | BN3: =IFERROR(BB3/X3*100,0) -> 0 | BO3: =IFERROR(BC3/Y3*100,0) -> 0 | BP3: =IFERROR(BD3/Z3*100,0) -> 0 | BQ3: =IFERROR(BE3/AA3*100,0) -> 0 | BR3: =IFERROR(BF3/AB3*100,0) -> 0 | BS3: =IFERROR(BG3/AC3*100,0) -> 0 | BT3: =IFERROR(BH3/AD3*100,0) -> 0 | BU3: =IFERROR(BI3/AE3*100,0) -> 0 | BV3: =(SUM(BA3:BI3)/SUM(W3:AE3))*100 -> 0 | BW3: =IF(BA3>0,1,0) -> 0 | BX3: =IF(BB3>0,1,0) -> 0 | BY3: =IF(BC3>0,1,0) -> 0 | BZ3: =IF(BD3>0,1,0) -> 0 | CA3: =IF(BE3>0,1,0) -> 0 | CB3: =IF(BF3>0,1,0) -> 0 | CC3: =IF(BG3>0,1,0) -> 0 | CD3: =IF(BH3>0,1,0) -> 0 | CE3: =IF(BI3>0,1,0) -> 0 | CG3: =BW3*W3 -> 0 | CH3: =BX3*X3 -> 0 | CI3: =BY3*Y3 -> 0 | CJ3: =BZ3*Z3 -> 0 | CK3: =CA3*AA3 -> 0 | CL3: =CB3*AB3 -> 0 | CM3: =CC3*AC3 -> 0 | CN3: =CD3*AD3 -> 0 | CO3: =CE3*AE3 -> 0
A4: =A3 -> Angola | B4: AEZ10 | C4: =_xlfn.CONCAT($A4,"#",$B4,"#",C$2) -> Angola#AEZ10#c_b | D4: =_xlfn.CONCAT($A4,"#",$B4,"#",D$2) -> Angola#AEZ10#ctl | E4: =_xlfn.CONCAT($A4,"#",$B4,"#",E$2) -> Angola#AEZ10#gro | F4: =_xlfn.CONCAT($A4,"#",$B4,"#",F$2) -> Angola#AEZ10#ocr | G4: =_xlfn.CONCAT($A4,"#",$B4,"#",G$2) -> Angola#AEZ10#osd | H4: =_xlfn.CONCAT($A4,"#",$B4,"#",H$2) -> Angola#AEZ10#pdr | I4: =_xlfn.CONCAT($A4,"#",$B4,"#",I$2) -> Angola#AEZ10#pfb | J4: =_xlfn.CONCAT($A4,"#",$B4,"#",J$2) -> Angola#AEZ10#v_f | K4: =_xlfn.CONCAT($A4,"#",$B4,"#",K$2) -> Angola#AEZ10#wht | M4: =IFERROR(_xlfn.IFNA(VLOOKUP(C4,Additional_LU_and_deforestation!$D:$E,2,FALSE)/VLOOKUP(C4,Land_Cover_MIN_MAX!$A:$C,2,FALSE),0),0) -> 0.54462059 | N4: =IFERROR(_xlfn.IFNA(VLOOKUP(D4,Additional_LU_and_deforestation!$D:$E,2,FALSE)/VLOOKUP(D4,Land_Cover_MIN_MAX!$A:$C,2,FALSE),0),0) -> 0.06108442 | O4: =IFERROR(_xlfn.IFNA(VLOOKUP(E4,Additional_LU_and_deforestation!$D:$E,2,FALSE)/VLOOKUP(E4,Land_Cover_MIN_MAX!$A:$C,2,FALSE),0),0) -> 3.0223148 | P4: =IFERROR(_xlfn.IFNA(VLOOKUP(F4,Additional_LU_and_deforestation!$D:$E,2,FALSE)/VLOOKUP(F4,Land_Cover_MIN_MAX!$A:$C,2,FALSE),0),0) -> 0.91005489 | Q4: =IFERROR(_xlfn.IFNA(VLOOKUP(G4,Additional_LU_and_deforestation!$D:$E,2,FALSE)/VLOOKUP(G4,Land_Cover_MIN_MAX!$A:$C,2,FALSE),0),0) -> 0.4505373 | R4: =IFERROR(_xlfn.IFNA(VLOOKUP(H4,Additional_LU_and_deforestation!$D:$E,2,FALSE)/VLOOKUP(H4,Land_Cover_MIN_MAX!$A:$C,2,FALSE),0),0) -> 1.0345729 | S4: =IFERROR(_xlfn.IFNA(VLOOKUP(I4,Additional_LU_and_deforestation!$D:$E,2,FALSE)/VLOOKUP(I4,Land_Cover_MIN_MAX!$A:$C,2,FALSE),0),0) -> 0.31656961 | T4: =IFERROR(_xlfn.IFNA(VLOOKUP(J4,Additional_LU_and_deforestation!$D:$E,2,FALSE)/VLOOKUP(J4,Land_Cover_MIN_MAX!$A:$C,2,FALSE),0),0) -> 0.66891404 | U4: =IFERROR(_xlfn.IFNA(VLOOKUP(K4,Additional_LU_and_deforestation!$D:$E,2,FALSE)/VLOOKUP(K4,Land_Cover_MIN_MAX!$A:$C,2,FALSE),0),0) -> 0.25970956 | W4: =VLOOKUP(C4,GTAP_area!$A:$F,6,FALSE) -> 1060 | X4: =VLOOKUP(D4,GTAP_area!$A:$F,6,FALSE) -> 4794460 | Y4: =VLOOKUP(E4,GTAP_area!$A:$F,6,FALSE) -> 593620 | Z4: =VLOOKUP(F4,GTAP_area!$A:$F,6,FALSE) -> 2500 | AA4: =VLOOKUP(G4,GTAP_area!$A:$F,6,FALSE) -> 21100 | AB4: =VLOOKUP(H4,GTAP_area!$A:$F,6,FALSE) -> 340 | AC4: =VLOOKUP(I4,GTAP_area!$A:$F,6,FALSE) -> 260 | AD4: =VLOOKUP(J4,GTAP_area!$A:$F,6,FALSE) -> 121840 | AE4: =VLOOKUP(K4,GTAP_area!$A:$F,6,FALSE) -> 340 | AG4: =M4*W4 -> 577.29783 | AH4: =N4*X4 -> 292866.81 | AI4: =O4*Y4 -> 1794106.5 | AJ4: =P4*Z4 -> 2275.1372 | AK4: =Q4*AA4 -> 9506.3371 | AL4: =R4*AB4 -> 351.75478 | AM4: =S4*AC4 -> 82.3081 | AN4: =T4*AD4 -> 81500.487 | AO4: =U4*AE4 -> 88.30125 | AQ4: =IFERROR(GETPIVOTDATA("Coef. GTAP",Sheet3!$A$3,"Country",$A4,"AEZ",$B4,"Name",AQ$2),0) -> 0.2649208 | AR4: =IFERROR(GETPIVOTDATA("Coef. GTAP",Sheet3!$A$3,"Country",$A4,"AEZ",$B4,"Name",AR$2),0) -> 0.77635099 | AS4: =IFERROR(GETPIVOTDATA("Coef. GTAP",Sheet3!$A$3,"Country",$A4,"AEZ",$B4,"Name",AS$2),0) -> 0.22818213 | AT4: =IFERROR(GETPIVOTDATA("Coef. GTAP",Sheet3!$A$3,"Country",$A4,"AEZ",$B4,"Name",AT$2),0) -> 0.21651891 | AU4: =IFERROR(GETPIVOTDATA("Coef. GTAP",Sheet3!$A$3,"Country",$A4,"AEZ",$B4,"Name",AU$2),0) -> 0.26058881 | AV4: =IFERROR(GETPIVOTDATA("Coef. GTAP",Sheet3!$A$3,"Country",$A4,"AEZ",$B4,"Name",AV$2),0) -> 0.27618208 | AW4: =IFERROR(GETPIVOTDATA("Coef. GTAP",Sheet3!$A$3,"Country",$A4,"AEZ",$B4,"Name",AW$2),0) -> 0.33129842 | AX4: =IFERROR(GETPIVOTDATA("Coef. GTAP",Sheet3!$A$3,"Country",$A4,"AEZ",$B4,"Name",AX$2),0) -> 0.23292312 | AY4: =IFERROR(GETPIVOTDATA("Coef. GTAP",Sheet3!$A$3,"Country",$A4,"AEZ",$B4,"Name",AY$2),0) -> 0.14632277 | BA4: =AG4*AQ4 -> 152.9382 | BB4: =AH4*AR4 -> 227367.44 | BC4: =AI4*AS4 -> 409383.05 | BD4: =AJ4*AT4 -> 492.61024 | BE4: =AK4*AU4 -> 2477.245 | BF4: =AL4*AV4 -> 97.148367 | BG4: =AM4*AW4 -> 27.268544 | BH4: =AN4*AX4 -> 18983.348 | BI4: =AO4*AY4 -> 12.920484 | BK4: =BK3 -> Angola | BL4: AEZ10 | BM4: =IFERROR(BA4/W4*100,0) -> 14.428132 | BN4: =IFERROR(BB4/X4*100,0) -> 4.742295 | BO4: =IFERROR(BC4/Y4*100,0) -> 68.963823 | BP4: =IFERROR(BD4/Z4*100,0) -> 19.704409 | BQ4: =IFERROR(BE4/AA4*100,0) -> 11.740498 | BR4: =IFERROR(BF4/AB4*100,0) -> 28.573049 | BS4: =IFERROR(BG4/AC4*100,0) -> 10.487901 | BT4: =IFERROR(BH4/AD4*100,0) -> 15.580555 | BU4: =IFERROR(BI4/AE4*100,0) -> 3.8001423 | BV4: =(SUM(BA4:BI4)/SUM(W4:AE4))*100 -> 11.904825 | BW4: =IF(BA4>0,1,0) -> 1 | BX4: =IF(BB4>0,1,0) -> 1 | BY4: =IF(BC4>0,1,0) -> 1 | BZ4: =IF(BD4>0,1,0) -> 1 | CA4: =IF(BE4>0,1,0) -> 1 | CB4: =IF(BF4>0,1,0) -> 1 | CC4: =IF(BG4>0,1,0) -> 1 | CD4: =IF(BH4>0,1,0) -> 1 | CE4: =IF(BI4>0,1,0) -> 1 | CG4: =BW4*W4 -> 1060 | CH4: =BX4*X4 -> 4794460 | CI4: =BY4*Y4 -> 593620 | CJ4: =BZ4*Z4 -> 2500 | CK4: =CA4*AA4 -> 21100 | CL4: =CB4*AB4 -> 340 | CM4: =CC4*AC4 -> 260 | CN4: =CD4*AD4 -> 121840 | CO4: =CE4*AE4 -> 340
A5: =A4 -> Angola | B5: AEZ11 | C5: =_xlfn.CONCAT($A5,"#",$B5,"#",C$2) -> Angola#AEZ11#c_b | D5: =_xlfn.CONCAT($A5,"#",$B5,"#",D$2) -> Angola#AEZ11#ctl | E5: =_xlfn.CONCAT($A5,"#",$B5,"#",E$2) -> Angola#AEZ11#gro | F5: =_xlfn.CONCAT($A5,"#",$B5,"#",F$2) -> Angola#AEZ11#ocr | G5: =_xlfn.CONCAT($A5,"#",$B5,"#",G$2) -> Angola#AEZ11#osd | H5: =_xlfn.CONCAT($A5,"#",$B5,"#",H$2) -> Angola#AEZ11#pdr | I5: =_xlfn.CONCAT($A5,"#",$B5,"#",I$2) -> Angola#AEZ11#pfb | J5: =_xlfn.CONCAT($A5,"#",$B5,"#",J$2) -> Angola#AEZ11#v_f | K5: =_xlfn.CONCAT($A5,"#",$B5,"#",K$2) -> Angola#AEZ11#wht | M5: =IFERROR(_xlfn.IFNA(VLOOKUP(C5,Additional_LU_and_deforestation!$D:$E,2,FALSE)/VLOOKUP(C5,Land_Cover_MIN_MAX!$A:$C,2,FALSE),0),0) -> 0.54462059 | N5: =IFERROR(_xlfn.IFNA(VLOOKUP(D5,Additional_LU_and_deforestation!$D:$E,2,FALSE)/VLOOKUP(D5,Land_Cover_MIN_MAX!$A:$C,2,FALSE),0),0) -> 0.18715996 | O5: =IFERROR(_xlfn.IFNA(VLOOKUP(E5,Additional_LU_and_deforestation!$D:$E,2,FALSE)/VLOOKUP(E5,Land_Cover_MIN_MAX!$A:$C,2,FALSE),0),0) -> 3.0223148 | P5: =IFERROR(_xlfn.IFNA(VLOOKUP(F5,Additional_LU_and_deforestation!$D:$E,2,FALSE)/VLOOKUP(F5,Land_Cover_MIN_MAX!$A:$C,2,FALSE),0),0) -> 0.91005489 | Q5: =IFERROR(_xlfn.IFNA(VLOOKUP(G5,Additional_LU_and_deforestation!$D:$E,2,FALSE)/VLOOKUP(G5,Land_Cover_MIN_MAX!$A:$C,2,FALSE),0),0) -> 0.4505373 | R5: =IFERROR(_xlfn.IFNA(VLOOKUP(H5,Additional_LU_and_deforestation!$D:$E,2,FALSE)/VLOOKUP(H5,Land_Cover_MIN_MAX!$A:$C,2,FALSE),0),0) -> 1.0345729 | S5: =IFERROR(_xlfn.IFNA(VLOOKUP(I5,Additional_LU_and_deforestation!$D:$E,2,FALSE)/VLOOKUP(I5,Land_Cover_MIN_MAX!$A:$C,2,FALSE),0),0) -> 0.31656961 | T5: =IFERROR(_xlfn.IFNA(VLOOKUP(J5,Additional_LU_and_deforestation!$D:$E,2,FALSE)/VLOOKUP(J5,Land_Cover_MIN_MAX!$A:$C,2,FALSE),0),0) -> 0.66891404 | U5: =IFERROR(_xlfn.IFNA(VLOOKUP(K5,Additional_LU_and_deforestation!$D:$E,2,FALSE)/VLOOKUP(K5,Land_Cover_MIN_MAX!$A:$C,2,FALSE),0),0) -> 0.25970956 | W5: =VLOOKUP(C5,GTAP_area!$A:$F,6,FALSE) -> 30 | X5: =VLOOKUP(D5,GTAP_area!$A:$F,6,FALSE) -> 1745130 | Y5: =VLOOKUP(E5,GTAP_area!$A:$F,6,FALSE) -> 10600 | Z5: =VLOOKUP(F5,GTAP_area!$A:$F,6,FALSE) -> 70 | AA5: =VLOOKUP(G5,GTAP_area!$A:$F,6,FALSE) -> 590 | AB5: =VLOOKUP(H5,GTAP_area!$A:$F,6,FALSE) -> 10 | AC5: =VLOOKUP(I5,GTAP_area!$A:$F,6,FALSE) -> 10 | AD5: =VLOOKUP(J5,GTAP_area!$A:$F,6,FALSE) -> 3420 | AE5: =VLOOKUP(K5,GTAP_area!$A:$F,6,FALSE) -> 10 | AG5: =M5*W5 -> 16.338618 | AH5: =N5*X5 -> 326618.45 | AI5: =O5*Y5 -> 32036.537 | AJ5: =P5*Z5 -> 63.703842 | AK5: =Q5*AA5 -> 265.81701 | AL5: =R5*AB5 -> 10.345729 | AM5: =S5*AC5 -> 3.1656961 | AN5: =T5*AD5 -> 2287.686 | AO5: =U5*AE5 -> 2.5970956 | AQ5: =IFERROR(GETPIVOTDATA("Coef. GTAP",Sheet3!$A$3,"Country",$A5,"AEZ",$B5,"Name",AQ$2),0) -> 1 | AR5: =IFERROR(GETPIVOTDATA("Coef. GTAP",Sheet3!$A$3,"Country",$A5,"AEZ",$B5,"Name",AR$2),0) -> 0.70155039 | AS5: =IFERROR(GETPIVOTDATA("Coef. GTAP",Sheet3!$A$3,"Country",$A5,"AEZ",$B5,"Name",AS$2),0) -> 1 | AT5: =IFERROR(GETPIVOTDATA("Coef. GTAP",Sheet3!$A$3,"Country",$A5,"AEZ",$B5,"Name",AT$2),0) -> 1 | AU5: =IFERROR(GETPIVOTDATA("Coef. GTAP",Sheet3!$A$3,"Country",$A5,"AEZ",$B5,"Name",AU$2),0) -> 1 | AV5: =IFERROR(GETPIVOTDATA("Coef. GTAP",Sheet3!$A$3,"Country",$A5,"AEZ",$B5,"Name",AV$2),0) -> 1 | AW5: =IFERROR(GETPIVOTDATA("Coef. GTAP",Sheet3!$A$3,"Country",$A5,"AEZ",$B5,"Name",AW$2),0) -> 1 | AX5: =IFERROR(GETPIVOTDATA("Coef. GTAP",Sheet3!$A$3,"Country",$A5,"AEZ",$B5,"Name",AX$2),0) -> 1 | AY5: =IFERROR(GETPIVOTDATA("Coef. GTAP",Sheet3!$A$3,"Country",$A5,"AEZ",$B5,"Name",AY$2),0) -> 1 | BA5: =AG5*AQ5 -> 16.338618 | BB5: =AH5*AR5 -> 229139.3 | BC5: =AI5*AS5 -> 32036.537 | BD5: =AJ5*AT5 -> 63.703842 | BE5: =AK5*AU5 -> 265.81701 | BF5: =AL5*AV5 -> 10.345729 | BG5: =AM5*AW5 -> 3.1656961 | BH5: =AN5*AX5 -> 2287.686 | BI5: =AO5*AY5 -> 2.5970956 | BK5: =BK4 -> Angola | BL5: AEZ11 | BM5: =IFERROR(BA5/W5*100,0) -> 54.462059 | BN5: =IFERROR(BB5/X5*100,0) -> 13.130214 | BO5: =IFERROR(BC5/Y5*100,0) -> 302.23148 | BP5: =IFERROR(BD5/Z5*100,0) -> 91.005489 | BQ5: =IFERROR(BE5/AA5*100,0) -> 45.05373 | BR5: =IFERROR(BF5/AB5*100,0) -> 103.45729 | BS5: =IFERROR(BG5/AC5*100,0) -> 31.656961 | BT5: =IFERROR(BH5/AD5*100,0) -> 66.891404 | BU5: =IFERROR(BI5/AE5*100,0) -> 25.970956 | BV5: =(SUM(BA5:BI5)/SUM(W5:AE5))*100 -> 14.991192 | BW5: =IF(BA5>0,1,0) -> 1 | BX5: =IF(BB5>0,1,0) -> 1 | BY5: =IF(BC5>0,1,0) -> 1 | BZ5: =IF(BD5>0,1,0) -> 1 | CA5: =IF(BE5>0,1,0) -> 1 | CB5: =IF(BF5>0,1,0) -> 1 | CC5: =IF(BG5>0,1,0) -> 1 | CD5: =IF(BH5>0,1,0) -> 1 | CE5: =IF(BI5>0,1,0) -> 1 | CG5: =BW5*W5 -> 30 | CH5: =BX5*X5 -> 1745130 | CI5: =BY5*Y5 -> 10600 | CJ5: =BZ5*Z5 -> 70 | CK5: =CA5*AA5 -> 590 | CL5: =CB5*AB5 -> 10 | CM5: =CC5*AC5 -> 10 | CN5: =CD5*AD5 -> 3420 | CO5: =CE5*AE5 -> 10
A6: =A5 -> Angola | B6: AEZ12 | C6: =_xlfn.CONCAT($A6,"#",$B6,"#",C$2) -> Angola#AEZ12#c_b | D6: =_xlfn.CONCAT($A6,"#",$B6,"#",D$2) -> Angola#AEZ12#ctl | E6: =_xlfn.CONCAT($A6,"#",$B6,"#",E$2) -> Angola#AEZ12#gro | F6: =_xlfn.CONCAT($A6,"#",$B6,"#",F$2) -> Angola#AEZ12#ocr | G6: =_xlfn.CONCAT($A6,"#",$B6,"#",G$2) -> Angola#AEZ12#osd | H6: =_xlfn.CONCAT($A6,"#",$B6,"#",H$2) -> Angola#AEZ12#pdr | I6: =_xlfn.CONCAT($A6,"#",$B6,"#",I$2) -> Angola#AEZ12#pfb | J6: =_xlfn.CONCAT($A6,"#",$B6,"#",J$2) -> Angola#AEZ12#v_f | K6: =_xlfn.CONCAT($A6,"#",$B6,"#",K$2) -> Angola#AEZ12#wht | M6: =IFERROR(_xlfn.IFNA(VLOOKUP(C6,Additional_LU_and_deforestation!$D:$E,2,FALSE)/VLOOKUP(C6,Land_Cover_MIN_MAX!$A:$C,2,FALSE),0),0) -> 0 | N6: =IFERROR(_xlfn.IFNA(VLOOKUP(D6,Additional_LU_and_deforestation!$D:$E,2,FALSE)/VLOOKUP(D6,Land_Cover_MIN_MAX!$A:$C,2,FALSE),0),0) -> 0 | O6: =IFERROR(_xlfn.IFNA(VLOOKUP(E6,Additional_LU_and_deforestation!$D:$E,2,FALSE)/VLOOKUP(E6,Land_Cover_MIN_MAX!$A:$C,2,FALSE),0),0) -> 0 | P6: =IFERROR(_xlfn.IFNA(VLOOKUP(F6,Additional_LU_and_deforestation!$D:$E,2,FALSE)/VLOOKUP(F6,Land_Cover_MIN_MAX!$A:$C,2,FALSE),0),0) -> 0 | Q6: =IFERROR(_xlfn.IFNA(VLOOKUP(G6,Additional_LU_and_deforestation!$D:$E,2,FALSE)/VLOOKUP(G6,Land_Cover_MIN_MAX!$A:$C,2,FALSE),0),0) -> 0 | R6: =IFERROR(_xlfn.IFNA(VLOOKUP(H6,Additional_LU_and_deforestation!$D:$E,2,FALSE)/VLOOKUP(H6,Land_Cover_MIN_MAX!$A:$C,2,FALSE),0),0) -> 0 | S6: =IFERROR(_xlfn.IFNA(VLOOKUP(I6,Additional_LU_and_deforestation!$D:$E,2,FALSE)/VLOOKUP(I6,Land_Cover_MIN_MAX!$A:$C,2,FALSE),0),0) -> 0 | T6: =IFERROR(_xlfn.IFNA(VLOOKUP(J6,Additional_LU_and_deforestation!$D:$E,2,FALSE)/VLOOKUP(J6,Land_Cover_MIN_MAX!$A:$C,2,FALSE),0),0) -> 0 | U6: =IFERROR(_xlfn.IFNA(VLOOKUP(K6,Additional_LU_and_deforestation!$D:$E,2,FALSE)/VLOOKUP(K6,Land_Cover_MIN_MAX!$A:$C,2,FALSE),0),0) -> 0 | W6: =VLOOKUP(C6,GTAP_area!$A:$F,6,FALSE) -> 0 | X6: =VLOOKUP(D6,GTAP_area!$A:$F,6,FALSE) -> 0 | Y6: =VLOOKUP(E6,GTAP_area!$A:$F,6,FALSE) -> 0 | Z6: =VLOOKUP(F6,GTAP_area!$A:$F,6,FALSE) -> 0 | AA6: =VLOOKUP(G6,GTAP_area!$A:$F,6,FALSE) -> 0 | AB6: =VLOOKUP(H6,GTAP_area!$A:$F,6,FALSE) -> 0 | AC6: =VLOOKUP(I6,GTAP_area!$A:$F,6,FALSE) -> 0 | AD6: =VLOOKUP(J6,GTAP_area!$A:$F,6,FALSE) -> 0 | AE6: =VLOOKUP(K6,GTAP_area!$A:$F,6,FALSE) -> 0 | AG6: =M6*W6 -> 0 | AH6: =N6*X6 -> 0 | AI6: =O6*Y6 -> 0 | AJ6: =P6*Z6 -> 0 | AK6: =Q6*AA6 -> 0 | AL6: =R6*AB6 -> 0 | AM6: =S6*AC6 -> 0 | AN6: =T6*AD6 -> 0 | AO6: =U6*AE6 -> 0 | AQ6: =IFERROR(GETPIVOTDATA("Coef. GTAP",Sheet3!$A$3,"Country",$A6,"AEZ",$B6,"Name",AQ$2),0) -> 0 | AR6: =IFERROR(GETPIVOTDATA("Coef. GTAP",Sheet3!$A$3,"Country",$A6,"AEZ",$B6,"Name",AR$2),0) -> 0 | AS6: =IFERROR(GETPIVOTDATA("Coef. GTAP",Sheet3!$A$3,"Country",$A6,"AEZ",$B6,"Name",AS$2),0) -> 0 | AT6: =IFERROR(GETPIVOTDATA("Coef. GTAP",Sheet3!$A$3,"Country",$A6,"AEZ",$B6,"Name",AT$2),0) -> 0 | AU6: =IFERROR(GETPIVOTDATA("Coef. GTAP",Sheet3!$A$3,"Country",$A6,"AEZ",$B6,"Name",AU$2),0) -> 0 | AV6: =IFERROR(GETPIVOTDATA("Coef. GTAP",Sheet3!$A$3,"Country",$A6,"AEZ",$B6,"Name",AV$2),0) -> 0 | AW6: =IFERROR(GETPIVOTDATA("Coef. GTAP",Sheet3!$A$3,"Country",$A6,"AEZ",$B6,"Name",AW$2),0) -> 0 | AX6: =IFERROR(GETPIVOTDATA("Coef. GTAP",Sheet3!$A$3,"Country",$A6,"AEZ",$B6,"Name",AX$2),0) -> 0 | AY6: =IFERROR(GETPIVOTDATA("Coef. GTAP",Sheet3!$A$3,"Country",$A6,"AEZ",$B6,"Name",AY$2),0) -> 0 | BA6: =AG6*AQ6 -> 0 | BB6: =AH6*AR6 -> 0 | BC6: =AI6*AS6 -> 0 | BD6: =AJ6*AT6 -> 0 | BE6: =AK6*AU6 -> 0 | BF6: =AL6*AV6 -> 0 | BG6: =AM6*AW6 -> 0 | BH6: =AN6*AX6 -> 0 | BI6: =AO6*AY6 -> 0 | BK6: =BK5 -> Angola | BL6: AEZ12 | BM6: =IFERROR(BA6/W6*100,0) -> 0 | BN6: =IFERROR(BB6/X6*100,0) -> 0 | BO6: =IFERROR(BC6/Y6*100,0) -> 0 | BP6: =IFERROR(BD6/Z6*100,0) -> 0 | BQ6: =IFERROR(BE6/AA6*100,0) -> 0 | BR6: =IFERROR(BF6/AB6*100,0) -> 0 | BS6: =IFERROR(BG6/AC6*100,0) -> 0 | BT6: =IFERROR(BH6/AD6*100,0) -> 0 | BU6: =IFERROR(BI6/AE6*100,0) -> 0 | BV6: =(SUM(BA6:BI6)/SUM(W6:AE6))*100 -> #DIV/0! | BW6: =IF(BA6>0,1,0) -> 0 | BX6: =IF(BB6>0,1,0) -> 0 | BY6: =IF(BC6>0,1,0) -> 0 | BZ6: =IF(BD6>0,1,0) -> 0 | CA6: =IF(BE6>0,1,0) -> 0 | CB6: =IF(BF6>0,1,0) -> 0 | CC6: =IF(BG6>0,1,0) -> 0 | CD6: =IF(BH6>0,1,0) -> 0 | CE6: =IF(BI6>0,1,0) -> 0 | CG6: =BW6*W6 -> 0 | CH6: =BX6*X6 -> 0 | CI6: =BY6*Y6 -> 0 | CJ6: =BZ6*Z6 -> 0 | CK6: =CA6*AA6 -> 0 | CL6: =CB6*AB6 -> 0 | CM6: =CC6*AC6 -> 0 | CN6: =CD6*AD6 -> 0 | CO6: =CE6*AE6 -> 0
A7: =A6 -> Angola | B7: AEZ13 | C7: =_xlfn.CONCAT($A7,"#",$B7,"#",C$2) -> Angola#AEZ13#c_b | D7: =_xlfn.CONCAT($A7,"#",$B7,"#",D$2) -> Angola#AEZ13#ctl | E7: =_xlfn.CONCAT($A7,"#",$B7,"#",E$2) -> Angola#AEZ13#gro | F7: =_xlfn.CONCAT($A7,"#",$B7,"#",F$2) -> Angola#AEZ13#ocr | G7: =_xlfn.CONCAT($A7,"#",$B7,"#",G$2) -> Angola#AEZ13#osd | H7: =_xlfn.CONCAT($A7,"#",$B7,"#",H$2) -> Angola#AEZ13#pdr | I7: =_xlfn.CONCAT($A7,"#",$B7,"#",I$2) -> Angola#AEZ13#pfb | J7: =_xlfn.CONCAT($A7,"#",$B7,"#",J$2) -> Angola#AEZ13#v_f | K7: =_xlfn.CONCAT($A7,"#",$B7,"#",K$2) -> Angola#AEZ13#wht | M7: =IFERROR(_xlfn.IFNA(VLOOKUP(C7,Additional_LU_and_deforestation!$D:$E,2,FALSE)/VLOOKUP(C7,Land_Cover_MIN_MAX!$A:$C,2,FALSE),0),0) -> 0 | N7: =IFERROR(_xlfn.IFNA(VLOOKUP(D7,Additional_LU_and_deforestation!$D:$E,2,FALSE)/VLOOKUP(D7,Land_Cover_MIN_MAX!$A:$C,2,FALSE),0),0) -> 0 | O7: =IFERROR(_xlfn.IFNA(VLOOKUP(E7,Additional_LU_and_deforestation!$D:$E,2,FALSE)/VLOOKUP(E7,Land_Cover_MIN_MAX!$A:$C,2,FALSE),0),0) -> 0 | P7: =IFERROR(_xlfn.IFNA(VLOOKUP(F7,Additional_LU_and_deforestation!$D:$E,2,FALSE)/VLOOKUP(F7,Land_Cover_MIN_MAX!$A:$C,2,FALSE),0),0) -> 0 | Q7: =IFERROR(_xlfn.IFNA(VLOOKUP(G7,Additional_LU_and_deforestation!$D:$E,2,FALSE)/VLOOKUP(G7,Land_Cover_MIN_MAX!$A:$C,2,FALSE),0),0) -> 0 | R7: =IFERROR(_xlfn.IFNA(VLOOKUP(H7,Additional_LU_and_deforestation!$D:$E,2,FALSE)/VLOOKUP(H7,Land_Cover_MIN_MAX!$A:$C,2,FALSE),0),0) -> 0 | S7: =IFERROR(_xlfn.IFNA(VLOOKUP(I7,Additional_LU_and_deforestation!$D:$E,2,FALSE)/VLOOKUP(I7,Land_Cover_MIN_MAX!$A:$C,2,FALSE),0),0) -> 0 | T7: =IFERROR(_xlfn.IFNA(VLOOKUP(J7,Additional_LU_and_deforestation!$D:$E,2,FALSE)/VLOOKUP(J7,Land_Cover_MIN_MAX!$A:$C,2,FALSE),0),0) -> 0 | U7: =IFERROR(_xlfn.IFNA(VLOOKUP(K7,Additional_LU_and_deforestation!$D:$E,2,FALSE)/VLOOKUP(K7,Land_Cover_MIN_MAX!$A:$C,2,FALSE),0),0) -> 0 | W7: =VLOOKUP(C7,GTAP_area!$A:$F,6,FALSE) -> 0 | X7: =VLOOKUP(D7,GTAP_area!$A:$F,6,FALSE) -> 0 | Y7: =VLOOKUP(E7,GTAP_area!$A:$F,6,FALSE) -> 0 | Z7: =VLOOKUP(F7,GTAP_area!$A:$F,6,FALSE) -> 0 | AA7: =VLOOKUP(G7,GTAP_area!$A:$F,6,FALSE) -> 0 | AB7: =VLOOKUP(H7,GTAP_area!$A:$F,6,FALSE) -> 0 | AC7: =VLOOKUP(I7,GTAP_area!$A:$F,6,FALSE) -> 0 | AD7: =VLOOKUP(J7,GTAP_area!$A:$F,6,FALSE) -> 0 | AE7: =VLOOKUP(K7,GTAP_area!$A:$F,6,FALSE) -> 0 | AG7: =M7*W7 -> 0 | AH7: =N7*X7 -> 0 | AI7: =O7*Y7 -> 0 | AJ7: =P7*Z7 -> 0 | AK7: =Q7*AA7 -> 0 | AL7: =R7*AB7 -> 0 | AM7: =S7*AC7 -> 0 | AN7: =T7*AD7 -> 0 | AO7: =U7*AE7 -> 0 | AQ7: =IFERROR(GETPIVOTDATA("Coef. GTAP",Sheet3!$A$3,"Country",$A7,"AEZ",$B7,"Name",AQ$2),0) -> 0 | AR7: =IFERROR(GETPIVOTDATA("Coef. GTAP",Sheet3!$A$3,"Country",$A7,"AEZ",$B7,"Name",AR$2),0) -> 0 | AS7: =IFERROR(GETPIVOTDATA("Coef. GTAP",Sheet3!$A$3,"Country",$A7,"AEZ",$B7,"Name",AS$2),0) -> 0 | AT7: =IFERROR(GETPIVOTDATA("Coef. GTAP",Sheet3!$A$3,"Country",$A7,"AEZ",$B7,"Name",AT$2),0) -> 0 | AU7: =IFERROR(GETPIVOTDATA("Coef. GTAP",Sheet3!$A$3,"Country",$A7,"AEZ",$B7,"Name",AU$2),0) -> 0 | AV7: =IFERROR(GETPIVOTDATA("Coef. GTAP",Sheet3!$A$3,"Country",$A7,"AEZ",$B7,"Name",AV$2),0) -> 0 | AW7: =IFERROR(GETPIVOTDATA("Coef. GTAP",Sheet3!$A$3,"Country",$A7,"AEZ",$B7,"Name",AW$2),0) -> 0 | AX7: =IFERROR(GETPIVOTDATA("Coef. GTAP",Sheet3!$A$3,"Country",$A7,"AEZ",$B7,"Name",AX$2),0) -> 0 | AY7: =IFERROR(GETPIVOTDATA("Coef. GTAP",Sheet3!$A$3,"Country",$A7,"AEZ",$B7,"Name",AY$2),0) -> 0 | BA7: =AG7*AQ7 -> 0 | BB7: =AH7*AR7 -> 0 | BC7: =AI7*AS7 -> 0 | BD7: =AJ7*AT7 -> 0 | BE7: =AK7*AU7 -> 0 | BF7: =AL7*AV7 -> 0 | BG7: =AM7*AW7 -> 0 | BH7: =AN7*AX7 -> 0 | BI7: =AO7*AY7 -> 0 | BK7: =BK6 -> Angola | BL7: AEZ13 | BM7: =IFERROR(BA7/W7*100,0) -> 0 | BN7: =IFERROR(BB7/X7*100,0) -> 0 | BO7: =IFERROR(BC7/Y7*100,0) -> 0 | BP7: =IFERROR(BD7/Z7*100,0) -> 0 | BQ7: =IFERROR(BE7/AA7*100,0) -> 0 | BR7: =IFERROR(BF7/AB7*100,0) -> 0 | BS7: =IFERROR(BG7/AC7*100,0) -> 0 | BT7: =IFERROR(BH7/AD7*100,0) -> 0 | BU7: =IFERROR(BI7/AE7*100,0) -> 0 | BV7: =(SUM(BA7:BI7)/SUM(W7:AE7))*100 -> #DIV/0! | BW7: =IF(BA7>0,1,0) -> 0 | BX7: =IF(BB7>0,1,0) -> 0 | BY7: =IF(BC7>0,1,0) -> 0 | BZ7: =IF(BD7>0,1,0) -> 0 | CA7: =IF(BE7>0,1,0) -> 0 | CB7: =IF(BF7>0,1,0) -> 0 | CC7: =IF(BG7>0,1,0) -> 0 | CD7: =IF(BH7>0,1,0) -> 0 | CE7: =IF(BI7>0,1,0) -> 0 | CG7: =BW7*W7 -> 0 | CH7: =BX7*X7 -> 0 | CI7: =BY7*Y7 -> 0 | CJ7: =BZ7*Z7 -> 0 | CK7: =CA7*AA7 -> 0 | CL7: =CB7*AB7 -> 0 | CM7: =CC7*AC7 -> 0 | CN7: =CD7*AD7 -> 0 | CO7: =CE7*AE7 -> 0
A8: =A7 -> Angola | B8: AEZ14 | C8: =_xlfn.CONCAT($A8,"#",$B8,"#",C$2) -> Angola#AEZ14#c_b | D8: =_xlfn.CONCAT($A8,"#",$B8,"#",D$2) -> Angola#AEZ14#ctl | E8: =_xlfn.CONCAT($A8,"#",$B8,"#",E$2) -> Angola#AEZ14#gro | F8: =_xlfn.CONCAT($A8,"#",$B8,"#",F$2) -> Angola#AEZ14#ocr | G8: =_xlfn.CONCAT($A8,"#",$B8,"#",G$2) -> Angola#AEZ14#osd | H8: =_xlfn.CONCAT($A8,"#",$B8,"#",H$2) -> Angola#AEZ14#pdr | I8: =_xlfn.CONCAT($A8,"#",$B8,"#",I$2) -> Angola#AEZ14#pfb | J8: =_xlfn.CONCAT($A8,"#",$B8,"#",J$2) -> Angola#AEZ14#v_f | K8: =_xlfn.CONCAT($A8,"#",$B8,"#",K$2) -> Angola#AEZ14#wht | M8: =IFERROR(_xlfn.IFNA(VLOOKUP(C8,Additional_LU_and_deforestation!$D:$E,2,FALSE)/VLOOKUP(C8,Land_Cover_MIN_MAX!$A:$C,2,FALSE),0),0) -> 0 | N8: =IFERROR(_xlfn.IFNA(VLOOKUP(D8,Additional_LU_and_deforestation!$D:$E,2,FALSE)/VLOOKUP(D8,Land_Cover_MIN_MAX!$A:$C,2,FALSE),0),0) -> 0 | O8: =IFERROR(_xlfn.IFNA(VLOOKUP(E8,Additional_LU_and_deforestation!$D:$E,2,FALSE)/VLOOKUP(E8,Land_Cover_MIN_MAX!$A:$C,2,FALSE),0),0) -> 0 | P8: =IFERROR(_xlfn.IFNA(VLOOKUP(F8,Additional_LU_and_deforestation!$D:$E,2,FALSE)/VLOOKUP(F8,Land_Cover_MIN_MAX!$A:$C,2,FALSE),0),0) -> 0 | Q8: =IFERROR(_xlfn.IFNA(VLOOKUP(G8,Additional_LU_and_deforestation!$D:$E,2,FALSE)/VLOOKUP(G8,Land_Cover_MIN_MAX!$A:$C,2,FALSE),0),0) -> 0 | R8: =IFERROR(_xlfn.IFNA(VLOOKUP(H8,Additional_LU_and_deforestation!$D:$E,2,FALSE)/VLOOKUP(H8,Land_Cover_MIN_MAX!$A:$C,2,FALSE),0),0) -> 0 | S8: =IFERROR(_xlfn.IFNA(VLOOKUP(I8,Additional_LU_and_deforestation!$D:$E,2,FALSE)/VLOOKUP(I8,Land_Cover_MIN_MAX!$A:$C,2,FALSE),0),0) -> 0 | T8: =IFERROR(_xlfn.IFNA(VLOOKUP(J8,Additional_LU_and_deforestation!$D:$E,2,FALSE)/VLOOKUP(J8,Land_Cover_MIN_MAX!$A:$C,2,FALSE),0),0) -> 0 | U8: =IFERROR(_xlfn.IFNA(VLOOKUP(K8,Additional_LU_and_deforestation!$D:$E,2,FALSE)/VLOOKUP(K8,Land_Cover_MIN_MAX!$A:$C,2,FALSE),0),0) -> 0 | W8: =VLOOKUP(C8,GTAP_area!$A:$F,6,FALSE) -> 0 | X8: =VLOOKUP(D8,GTAP_area!$A:$F,6,FALSE) -> 0 | Y8: =VLOOKUP(E8,GTAP_area!$A:$F,6,FALSE) -> 0 | Z8: =VLOOKUP(F8,GTAP_area!$A:$F,6,FALSE) -> 0 | AA8: =VLOOKUP(G8,GTAP_area!$A:$F,6,FALSE) -> 0 | AB8: =VLOOKUP(H8,GTAP_area!$A:$F,6,FALSE) -> 0 | AC8: =VLOOKUP(I8,GTAP_area!$A:$F,6,FALSE) -> 0 | AD8: =VLOOKUP(J8,GTAP_area!$A:$F,6,FALSE) -> 0 | AE8: =VLOOKUP(K8,GTAP_area!$A:$F,6,FALSE) -> 0 | AG8: =M8*W8 -> 0 | AH8: =N8*X8 -> 0 | AI8: =O8*Y8 -> 0 | AJ8: =P8*Z8 -> 0 | AK8: =Q8*AA8 -> 0 | AL8: =R8*AB8 -> 0 | AM8: =S8*AC8 -> 0 | AN8: =T8*AD8 -> 0 | AO8: =U8*AE8 -> 0 | AQ8: =IFERROR(GETPIVOTDATA("Coef. GTAP",Sheet3!$A$3,"Country",$A8,"AEZ",$B8,"Name",AQ$2),0) -> 0 | AR8: =IFERROR(GETPIVOTDATA("Coef. GTAP",Sheet3!$A$3,"Country",$A8,"AEZ",$B8,"Name",AR$2),0) -> 0 | AS8: =IFERROR(GETPIVOTDATA("Coef. GTAP",Sheet3!$A$3,"Country",$A8,"AEZ",$B8,"Name",AS$2),0) -> 0 | AT8: =IFERROR(GETPIVOTDATA("Coef. GTAP",Sheet3!$A$3,"Country",$A8,"AEZ",$B8,"Name",AT$2),0) -> 0 | AU8: =IFERROR(GETPIVOTDATA("Coef. GTAP",Sheet3!$A$3,"Country",$A8,"AEZ",$B8,"Name",AU$2),0) -> 0 | AV8: =IFERROR(GETPIVOTDATA("Coef. GTAP",Sheet3!$A$3,"Country",$A8,"AEZ",$B8,"Name",AV$2),0) -> 0 | AW8: =IFERROR(GETPIVOTDATA("Coef. GTAP",Sheet3!$A$3,"Country",$A8,"AEZ",$B8,"Name",AW$2),0) -> 0 | AX8: =IFERROR(GETPIVOTDATA("Coef. GTAP",Sheet3!$A$3,"Country",$A8,"AEZ",$B8,"Name",AX$2),0) -> 0 | AY8: =IFERROR(GETPIVOTDATA("Coef. GTAP",Sheet3!$A$3,"Country",$A8,"AEZ",$B8,"Name",AY$2),0) -> 0 | BA8: =AG8*AQ8 -> 0 | BB8: =AH8*AR8 -> 0 | BC8: =AI8*AS8 -> 0 | BD8: =AJ8*AT8 -> 0 | BE8: =AK8*AU8 -> 0 | BF8: =AL8*AV8 -> 0 | BG8: =AM8*AW8 -> 0 | BH8: =AN8*AX8 -> 0 | BI8: =AO8*AY8 -> 0 | BK8: =BK7 -> Angola | BL8: AEZ14 | BM8: =IFERROR(BA8/W8*100,0) -> 0 | BN8: =IFERROR(BB8/X8*100,0) -> 0 | BO8: =IFERROR(BC8/Y8*100,0) -> 0 | BP8: =IFERROR(BD8/Z8*100,0) -> 0 | BQ8: =IFERROR(BE8/AA8*100,0) -> 0 | BR8: =IFERROR(BF8/AB8*100,0) -> 0 | BS8: =IFERROR(BG8/AC8*100,0) -> 0 | BT8: =IFERROR(BH8/AD8*100,0) -> 0 | BU8: =IFERROR(BI8/AE8*100,0) -> 0 | BV8: =(SUM(BA8:BI8)/SUM(W8:AE8))*100 -> #DIV/0! | BW8: =IF(BA8>0,1,0) -> 0 | BX8: =IF(BB8>0,1,0) -> 0 | BY8: =IF(BC8>0,1,0) -> 0 | BZ8: =IF(BD8>0,1,0) -> 0 | CA8: =IF(BE8>0,1,0) -> 0 | CB8: =IF(BF8>0,1,0) -> 0 | CC8: =IF(BG8>0,1,0) -> 0 | CD8: =IF(BH8>0,1,0) -> 0 | CE8: =IF(BI8>0,1,0) -> 0 | CG8: =BW8*W8 -> 0 | CH8: =BX8*X8 -> 0 | CI8: =BY8*Y8 -> 0 | CJ8: =BZ8*Z8 -> 0 | CK8: =CA8*AA8 -> 0 | CL8: =CB8*AB8 -> 0 | CM8: =CC8*AC8 -> 0 | CN8: =CD8*AD8 -> 0 | CO8: =CE8*AE8 -> 0
A9: =A8 -> Angola | B9: AEZ15 | C9: =_xlfn.CONCAT($A9,"#",$B9,"#",C$2) -> Angola#AEZ15#c_b | D9: =_xlfn.CONCAT($A9,"#",$B9,"#",D$2) -> Angola#AEZ15#ctl | E9: =_xlfn.CONCAT($A9,"#",$B9,"#",E$2) -> Angola#AEZ15#gro | F9: =_xlfn.CONCAT($A9,"#",$B9,"#",F$2) -> Angola#AEZ15#ocr | G9: =_xlfn.CONCAT($A9,"#",$B9,"#",G$2) -> Angola#AEZ15#osd | H9: =_xlfn.CONCAT($A9,"#",$B9,"#",H$2) -> Angola#AEZ15#pdr | I9: =_xlfn.CONCAT($A9,"#",$B9,"#",I$2) -> Angola#AEZ15#pfb | J9: =_xlfn.CONCAT($A9,"#",$B9,"#",J$2) -> Angola#AEZ15#v_f | K9: =_xlfn.CONCAT($A9,"#",$B9,"#",K$2) -> Angola#AEZ15#wht | M9: =IFERROR(_xlfn.IFNA(VLOOKUP(C9,Additional_LU_and_deforestation!$D:$E,2,FALSE)/VLOOKUP(C9,Land_Cover_MIN_MAX!$A:$C,2,FALSE),0),0) -> 0 | N9: =IFERROR(_xlfn.IFNA(VLOOKUP(D9,Additional_LU_and_deforestation!$D:$E,2,FALSE)/VLOOKUP(D9,Land_Cover_MIN_MAX!$A:$C,2,FALSE),0),0) -> 0 | O9: =IFERROR(_xlfn.IFNA(VLOOKUP(E9,Additional_LU_and_deforestation!$D:$E,2,FALSE)/VLOOKUP(E9,Land_Cover_MIN_MAX!$A:$C,2,FALSE),0),0) -> 0 | P9: =IFERROR(_xlfn.IFNA(VLOOKUP(F9,Additional_LU_and_deforestation!$D:$E,2,FALSE)/VLOOKUP(F9,Land_Cover_MIN_MAX!$A:$C,2,FALSE),0),0) -> 0 | Q9: =IFERROR(_xlfn.IFNA(VLOOKUP(G9,Additional_LU_and_deforestation!$D:$E,2,FALSE)/VLOOKUP(G9,Land_Cover_MIN_MAX!$A:$C,2,FALSE),0),0) -> 0 | R9: =IFERROR(_xlfn.IFNA(VLOOKUP(H9,Additional_LU_and_deforestation!$D:$E,2,FALSE)/VLOOKUP(H9,Land_Cover_MIN_MAX!$A:$C,2,FALSE),0),0) -> 0 | S9: =IFERROR(_xlfn.IFNA(VLOOKUP(I9,Additional_LU_and_deforestation!$D:$E,2,FALSE)/VLOOKUP(I9,Land_Cover_MIN_MAX!$A:$C,2,FALSE),0),0) -> 0 | T9: =IFERROR(_xlfn.IFNA(VLOOKUP(J9,Additional_LU_and_deforestation!$D:$E,2,FALSE)/VLOOKUP(J9,Land_Cover_MIN_MAX!$A:$C,2,FALSE),0),0) -> 0 | U9: =IFERROR(_xlfn.IFNA(VLOOKUP(K9,Additional_LU_and_deforestation!$D:$E,2,FALSE)/VLOOKUP(K9,Land_Cover_MIN_MAX!$A:$C,2,FALSE),0),0) -> 0 | W9: =VLOOKUP(C9,GTAP_area!$A:$F,6,FALSE) -> 0 | X9: =VLOOKUP(D9,GTAP_area!$A:$F,6,FALSE) -> 0 | Y9: =VLOOKUP(E9,GTAP_area!$A:$F,6,FALSE) -> 0 | Z9: =VLOOKUP(F9,GTAP_area!$A:$F,6,FALSE) -> 0 | AA9: =VLOOKUP(G9,GTAP_area!$A:$F,6,FALSE) -> 0 | AB9: =VLOOKUP(H9,GTAP_area!$A:$F,6,FALSE) -> 0 | AC9: =VLOOKUP(I9,GTAP_area!$A:$F,6,FALSE) -> 0 | AD9: =VLOOKUP(J9,GTAP_area!$A:$F,6,FALSE) -> 0 | AE9: =VLOOKUP(K9,GTAP_area!$A:$F,6,FALSE) -> 0 | AG9: =M9*W9 -> 0 | AH9: =N9*X9 -> 0 | AI9: =O9*Y9 -> 0 | AJ9: =P9*Z9 -> 0 | AK9: =Q9*AA9 -> 0 | AL9: =R9*AB9 -> 0 | AM9: =S9*AC9 -> 0 | AN9: =T9*AD9 -> 0 | AO9: =U9*AE9 -> 0 | AQ9: =IFERROR(GETPIVOTDATA("Coef. GTAP",Sheet3!$A$3,"Country",$A9,"AEZ",$B9,"Name",AQ$2),0) -> 0 | AR9: =IFERROR(GETPIVOTDATA("Coef. GTAP",Sheet3!$A$3,"Country",$A9,"AEZ",$B9,"Name",AR$2),0) -> 0 | AS9: =IFERROR(GETPIVOTDATA("Coef. GTAP",Sheet3!$A$3,"Country",$A9,"AEZ",$B9,"Name",AS$2),0) -> 0 | AT9: =IFERROR(GETPIVOTDATA("Coef. GTAP",Sheet3!$A$3,"Country",$A9,"AEZ",$B9,"Name",AT$2),0) -> 0 | AU9: =IFERROR(GETPIVOTDATA("Coef. GTAP",Sheet3!$A$3,"Country",$A9,"AEZ",$B9,"Name",AU$2),0) -> 0 | AV9: =IFERROR(GETPIVOTDATA("Coef. GTAP",Sheet3!$A$3,"Country",$A9,"AEZ",$B9,"Name",AV$2),0) -> 0 | AW9: =IFERROR(GETPIVOTDATA("Coef. GTAP",Sheet3!$A$3,"Country",$A9,"AEZ",$B9,"Name",AW$2),0) -> 0 | AX9: =IFERROR(GETPIVOTDATA("Coef. GTAP",Sheet3!$A$3,"Country",$A9,"AEZ",$B9,"Name",AX$2),0) -> 0 | AY9: =IFERROR(GETPIVOTDATA("Coef. GTAP",Sheet3!$A$3,"Country",$A9,"AEZ",$B9,"Name",AY$2),0) -> 0 | BA9: =AG9*AQ9 -> 0 | BB9: =AH9*AR9 -> 0 | BC9: =AI9*AS9 -> 0 | BD9: =AJ9*AT9 -> 0 | BE9: =AK9*AU9 -> 0 | BF9: =AL9*AV9 -> 0 | BG9: =AM9*AW9 -> 0 | BH9: =AN9*AX9 -> 0 | BI9: =AO9*AY9 -> 0 | BK9: =BK8 -> Angola | BL9: AEZ15 | BM9: =IFERROR(BA9/W9*100,0) -> 0 | BN9: =IFERROR(BB9/X9*100,0) -> 0 | BO9: =IFERROR(BC9/Y9*100,0) -> 0 | BP9: =IFERROR(BD9/Z9*100,0) -> 0 | BQ9: =IFERROR(BE9/AA9*100,0) -> 0 | BR9: =IFERROR(BF9/AB9*100,0) -> 0 | BS9: =IFERROR(BG9/AC9*100,0) -> 0 | BT9: =IFERROR(BH9/AD9*100,0) -> 0 | BU9: =IFERROR(BI9/AE9*100,0) -> 0 | BV9: =(SUM(BA9:BI9)/SUM(W9:AE9))*100 -> #DIV/0! | BW9: =IF(BA9>0,1,0) -> 0 | BX9: =IF(BB9>0,1,0) -> 0 | BY9: =IF(BC9>0,1,0) -> 0 | BZ9: =IF(BD9>0,1,0) -> 0 | CA9: =IF(BE9>0,1,0) -> 0 | CB9: =IF(BF9>0,1,0) -> 0 | CC9: =IF(BG9>0,1,0) -> 0 | CD9: =IF(BH9>0,1,0) -> 0 | CE9: =IF(BI9>0,1,0) -> 0 | CG9: =BW9*W9 -> 0 | CH9: =BX9*X9 -> 0 | CI9: =BY9*Y9 -> 0 | CJ9: =BZ9*Z9 -> 0 | CK9: =CA9*AA9 -> 0 | CL9: =CB9*AB9 -> 0 | CM9: =CC9*AC9 -> 0 | CN9: =CD9*AD9 -> 0 | CO9: =CE9*AE9 -> 0
